Workbook
Name mn: #REF!
Name Print_Area: NOCH!$A$1:$AU$46
Name Print_Area: RSCH!$A$1:$AU$46
Name Print_Area_0: Дулов!$A$1:$AZ$40
Name Print_Titles: Горбуненко!$7:$7
Name Print_Titles: Дулов!$7:$7
Name Print_Titles: Карпенко!$7:$7
Name Print_Titles: Климов!$7:$7
Name Print_Titles: Колодный!$7:$7
Name Print_Titles: Котов!$7:$7
Name Print_Titles: Кривоконев!$7:$7
Name Print_Titles: 'Лахин В'!$7:$7
Name Print_Titles: 'Лахин С'!$7:$7
Name Print_Titles: Миньков!$7:$7
Name Print_Titles: Никонов!$7:$7
Name Print_Titles: Переверзев!$7:$7
Name Print_Titles: Рудиков!$7:$7
Name Print_Titles: Табалин!$7:$7
Name Print_Titles: Толстиков!$7:$7
Name Print_Titles: Федюшкин!$7:$7
Name yr: #REF!

Sheet Main
C1: АО Риф, ООО Стимул | AU1: Унифицированная форма № Т-13
C2: наименование организации | AU2: Утверждена постановлением Госкомстата РФ
C3: ПК №250 | X3: Принятые | AU3: от 5 января 2004 г. N 1
C4: наименование структурного подразделения
A5: ТАБЕЛЬ | AU5: 14
A6: учета использования рабочего времени
A7: =CONCATENATE("за ",данные!A1," месяц ",данные!B1) -> за февраль месяц 2026 года.
A8: № п/п | B8: Табельный номер | C8: Фамилия, инициалы, должность (специальность, профессия) | D8: Профессия | E8: Отметки о явках и неявках на работу по числам месяца | AJ8: Отработано за
E9: 01 | F9: 02 | G9: 03 | H9: 04 | I9: 05 | J9: 06 | K9: 07 | L9: 08 | M9: 09 | N9: 10 | O9: 11 | P9: 12 | Q9: 13 | R9: 14 | S9: 15 | T9: 16 | U9: 17 | V9: 18 | W9: 19 | X9: 20 | Y9: 21 | Z9: 22 | AA9: 23 | AB9: 24 | AC9: 25 | AD9: 26 | AE9: 27 | AF9: 28 | AG9: 29 | AH9: 30 | AI9: 31 | AJ9: Месяц | AR9: Отработано | AT9: Всего
AJ10: командиров. | AK10: прогул | AL10: боль-нич- ный | AM10: отпуск | AN10: адм. отп | AO10: празд вы- ходн | AP10: ночн. | AQ10: пере-работ- ка | AR10: дней | AS10: часов | AT10: дней | AU10: часов
A11: 1 | C11: 2 | D11: 3 | E11: 4 | AJ11: 5 | AK11: 6 | AL11: 7 | AM11: 8 | AN11: 9 | AO11: 10 | AP11: 11 | AQ11: 12 | AR11: 13 | AS11: 14 | AT11: 15 | AU11: 16
B12: АО Риф
A13: 1 | B13: 83727 | C13: Горбуненко Ф.Ф. | D13: слес-рем | F13: 8 | G13: 4 | H13: А | I13: 8 | J13: 8 | K13: 7 | L13: 7 | AJ13: =IF(RSCH!AJ13=0,"",RSCH!AJ13) | AK13: =IF(RSCH!AK13=0,"",RSCH!AK13) | AL13: =IF(RSCH!AL13=0,"",RSCH!AL13) | AM13: =IF(RSCH!AM13=0,"",RSCH!AM13) | AN13: =IF(RSCH!AN13=0,"",RSCH!AN13) | AO13: =IF(RSCH!AO13=0,"",RSCH!AO13) -> 14 | AP13: =IF(NOCH!AP13=0,"",NOCH!AP13) | AQ13: =IF(AS13="","",IF((AS13-AU13)>0,AS13-AU13,"")) | AR13: =IF(RSCH!AR13=0,"",RSCH!AR13) -> 6 | AS13: =IF(RSCH!AS13=0,"",RSCH!AS13) -> 42 | AT13: =NOCH!AT13 -> 19 | AU13: =NOCH!AU13 -> 152
A14: 2 | B14: 89046 | C14: Дулов С.Д. | D14: слес-рем | F14: 8 | G14: 8 | H14: 8 | I14: 8 | J14: 8 | K14: 7 | AJ14: =IF(RSCH!AJ14=0,"",RSCH!AJ14) | AK14: =IF(RSCH!AK14=0,"",RSCH!AK14) | AL14: =IF(RSCH!AL14=0,"",RSCH!AL14) | AM14: =IF(RSCH!AM14=0,"",RSCH!AM14) | AN14: =IF(RSCH!AN14=0,"",RSCH!AN14) | AO14: =IF(RSCH!AO14=0,"",RSCH!AO14) -> 7 | AP14: =IF(NOCH!AP14=0,"",NOCH!AP14) | AQ14: =IF(AS14="","",IF((AS14-AU14)>0,AS14-AU14,"")) | AR14: =IF(RSCH!AR14=0,"",RSCH!AR14) -> 6 | AS14: =IF(RSCH!AS14=0,"",RSCH!AS14) -> 47 | AT14: =NOCH!AT14 -> 19 | AU14: =NOCH!AU14 -> 152
A15: 3 | B15: 31205 | C15: Карпенко А.Г. | D15: слес-рем | E15: О | F15: О | G15: О | H15: О | I15: О | J15: О | K15: О | L15: О | AJ15: =IF(RSCH!AJ15=0,"",RSCH!AJ15) | AK15: =IF(RSCH!AK15=0,"",RSCH!AK15) | AL15: =IF(RSCH!AL15=0,"",RSCH!AL15) | AM15: =IF(RSCH!AM15=0,"",RSCH!AM15) -> 8 | AN15: =IF(RSCH!AN15=0,"",RSCH!AN15) | AO15: =IF(RSCH!AO15=0,"",RSCH!AO15) | AP15: =IF(NOCH!AP15=0,"",NOCH!AP15) | AQ15: =IF(AS15="","",IF((AS15-AU15)>0,AS15-AU15,"")) | AR15: =IF(RSCH!AR15=0,"",RSCH!AR15) | AS15: =IF(RSCH!AS15=0,"",RSCH!AS15) | AT15: =NOCH!AT15 | AU15: =NOCH!AU15
A16: 4 | B16: 83448 | C16: Колодный С.С. | D16: эл/мех | E16: 7 | F16: А | G16: 8 | H16: 8 | I16: 8 | J16: 8 | AJ16: =IF(RSCH!AJ16=0,"",RSCH!AJ16) | AK16: =IF(RSCH!AK16=0,"",RSCH!AK16) | AL16: =IF(RSCH!AL16=0,"",RSCH!AL16) | AM16: =IF(RSCH!AM16=0,"",RSCH!AM16) | AN16: =IF(RSCH!AN16=0,"",RSCH!AN16) | AO16: =IF(RSCH!AO16=0,"",RSCH!AO16) -> 7 | AP16: =IF(NOCH!AP16=0,"",NOCH!AP16) | AQ16: =IF(AS16="","",IF((AS16-AU16)>0,AS16-AU16,"")) | AR16: =IF(RSCH!AR16=0,"",RSCH!AR16) -> 5 | AS16: =IF(RSCH!AS16=0,"",RSCH!AS16) -> 39 | AT16: =NOCH!AT16 -> 19 | AU16: =NOCH!AU16 -> 152
A17: 5 | B17: 21782 | C17: Котов О.А. | D17: слес-рем | E17: 7 | F17: 8 | G17: 8 | H17: 8 | I17: 8 | J17: 8 | AJ17: =IF(RSCH!AJ17=0,"",RSCH!AJ17) | AK17: =IF(RSCH!AK17=0,"",RSCH!AK17) | AL17: =IF(RSCH!AL17=0,"",RSCH!AL17) | AM17: =IF(RSCH!AM17=0,"",RSCH!AM17) | AN17: =IF(RSCH!AN17=0,"",RSCH!AN17) | AO17: =IF(RSCH!AO17=0,"",RSCH!AO17) -> 7 | AP17: =IF(NOCH!AP17=0,"",NOCH!AP17) | AQ17: =IF(AS17="","",IF((AS17-AU17)>0,AS17-AU17,"")) | AR17: =IF(RSCH!AR17=0,"",RSCH!AR17) -> 6 | AS17: =IF(RSCH!AS17=0,"",RSCH!AS17) -> 47 | AT17: =NOCH!AT17 -> 19 | AU17: =NOCH!AU17 -> 152
A18: 6 | B18: 90072 | C18: Кривоконев В.И. | D18: слес-рем | F18: 8 | G18: 8 | H18: 8 | I18: 8 | J18: 8 | AJ18: =IF(RSCH!AJ18=0,"",RSCH!AJ18) | AK18: =IF(RSCH!AK18=0,"",RSCH!AK18) | AL18: =IF(RSCH!AL18=0,"",RSCH!AL18) | AM18: =IF(RSCH!AM18=0,"",RSCH!AM18) | AN18: =IF(RSCH!AN18=0,"",RSCH!AN18) | AO18: =IF(RSCH!AO18=0,"",RSCH!AO18) | AP18: =IF(NOCH!AP18=0,"",NOCH!AP18) | AQ18: =IF(AS18="","",IF((AS18-AU18)>0,AS18-AU18,"")) | AR18: =IF(RSCH!AR18=0,"",RSCH!AR18) -> 5 | AS18: =IF(RSCH!AS18=0,"",RSCH!AS18) -> 40 | AT18: =NOCH!AT18 -> 19 | AU18: =NOCH!AU18 -> 152
A19: 7 | B19: 63549 | C19: Лахин В.В. | D19: слес-рем | F19: 8 | G19: 8 | H19: 8 | I19: 8 | J19: 8 | AJ19: =IF(RSCH!AJ19=0,"",RSCH!AJ19) | AK19: =IF(RSCH!AK19=0,"",RSCH!AK19) | AL19: =IF(RSCH!AL19=0,"",RSCH!AL19) | AM19: =IF(RSCH!AM19=0,"",RSCH!AM19) | AN19: =IF(RSCH!AN19=0,"",RSCH!AN19) | AO19: =IF(RSCH!AO19=0,"",RSCH!AO19) | AP19: =IF(NOCH!AP19=0,"",NOCH!AP19) | AQ19: =IF(AS19="","",IF((AS19-AU19)>0,AS19-AU19,"")) | AR19: =IF(RSCH!AR19=0,"",RSCH!AR19) -> 5 | AS19: =IF(RSCH!AS19=0,"",RSCH!AS19) -> 40 | AT19: =NOCH!AT19 -> 19 | AU19: =NOCH!AU19 -> 152
A20: 8 | B20: 12377 | C20: Лахин С.Н. | D20: слес-рем | F20: 8 | G20: 8 | H20: 8 | I20: 8 | J20: 8 | AJ20: =IF(RSCH!AJ20=0,"",RSCH!AJ20) | AK20: =IF(RSCH!AK20=0,"",RSCH!AK20) | AL20: =IF(RSCH!AL20=0,"",RSCH!AL20) | AM20: =IF(RSCH!AM20=0,"",RSCH!AM20) | AN20: =IF(RSCH!AN20=0,"",RSCH!AN20) | AO20: =IF(RSCH!AO20=0,"",RSCH!AO20) | AP20: =IF(NOCH!AP20=0,"",NOCH!AP20) | AQ20: =IF(AS20="","",IF((AS20-AU20)>0,AS20-AU20,"")) | AR20: =IF(RSCH!AR20=0,"",RSCH!AR20) -> 5 | AS20: =IF(RSCH!AS20=0,"",RSCH!AS20) -> 40 | AT20: =NOCH!AT20 -> 19 | AU20: =NOCH!AU20 -> 152
A21: 9 | B21: 63558 | C21: Миньков А.А. | D21: слес-рем | E21: О | F21: О | G21: О | H21: О | I21: О | J21: О | K21: О | L21: О | AJ21: =IF(RSCH!AJ21=0,"",RSCH!AJ21) | AK21: =IF(RSCH!AK21=0,"",RSCH!AK21) | AL21: =IF(RSCH!AL21=0,"",RSCH!AL21) | AM21: =IF(RSCH!AM21=0,"",RSCH!AM21) -> 8 | AN21: =IF(RSCH!AN21=0,"",RSCH!AN21) | AO21: =IF(RSCH!AO21=0,"",RSCH!AO21) | AP21: =IF(NOCH!AP21=0,"",NOCH!AP21) | AQ21: =IF(AS21="","",IF((AS21-AU21)>0,AS21-AU21,"")) | AR21: =IF(RSCH!AR21=0,"",RSCH!AR21) | AS21: =IF(RSCH!AS21=0,"",RSCH!AS21) | AT21: =NOCH!AT21 | AU21: =NOCH!AU21
A22: 10 | B22: 31178 | C22: Никонов Н.А. | D22: слес-рем | F22: 8 | G22: 8 | H22: 8 | I22: 8 | J22: 8 | AJ22: =IF(RSCH!AJ22=0,"",RSCH!AJ22) | AK22: =IF(RSCH!AK22=0,"",RSCH!AK22) | AL22: =IF(RSCH!AL22=0,"",RSCH!AL22) | AM22: =IF(RSCH!AM22=0,"",RSCH!AM22) | AN22: =IF(RSCH!AN22=0,"",RSCH!AN22) | AO22: =IF(RSCH!AO22=0,"",RSCH!AO22) | AP22: =IF(NOCH!AP22=0,"",NOCH!AP22) | AQ22: =IF(AS22="","",IF((AS22-AU22)>0,AS22-AU22,"")) | AR22: =IF(RSCH!AR22=0,"",RSCH!AR22) -> 5 | AS22: =IF(RSCH!AS22=0,"",RSCH!AS22) -> 40 | AT22: =NOCH!AT22 -> 19 | AU22: =NOCH!AU22 -> 152
A23: 11 | B23: 21116 | C23: Переверзев А.М. | D23: слес-рем | F23: 8 | G23: 8 | H23: 8 | I23: 8 | J23: 8 | AJ23: =IF(RSCH!AJ23=0,"",RSCH!AJ23) | AK23: =IF(RSCH!AK23=0,"",RSCH!AK23) | AL23: =IF(RSCH!AL23=0,"",RSCH!AL23) | AM23: =IF(RSCH!AM23=0,"",RSCH!AM23) | AN23: =IF(RSCH!AN23=0,"",RSCH!AN23) | AO23: =IF(RSCH!AO23=0,"",RSCH!AO23) | AP23: =IF(NOCH!AP23=0,"",NOCH!AP23) | AQ23: =IF(AS23="","",IF((AS23-AU23)>0,AS23-AU23,"")) | AR23: =IF(RSCH!AR23=0,"",RSCH!AR23) -> 5 | AS23: =IF(RSCH!AS23=0,"",RSCH!AS23) -> 40 | AT23: =NOCH!AT23 -> 19 | AU23: =NOCH!AU23 -> 152
A24: 12 | B24: 66051 | C24: Табалин П.А. | D24: эл/мех | F24: 8 | G24: 8 | H24: 8 | I24: 8 | J24: 8 | AJ24: =IF(RSCH!AJ24=0,"",RSCH!AJ24) | AK24: =IF(RSCH!AK24=0,"",RSCH!AK24) | AL24: =IF(RSCH!AL24=0,"",RSCH!AL24) | AM24: =IF(RSCH!AM24=0,"",RSCH!AM24) | AN24: =IF(RSCH!AN24=0,"",RSCH!AN24) | AO24: =IF(RSCH!AO24=0,"",RSCH!AO24) | AP24: =IF(NOCH!AP24=0,"",NOCH!AP24) | AQ24: =IF(AS24="","",IF((AS24-AU24)>0,AS24-AU24,"")) | AR24: =IF(RSCH!AR24=0,"",RSCH!AR24) -> 5 | AS24: =IF(RSCH!AS24=0,"",RSCH!AS24) -> 40 | AT24: =NOCH!AT24 -> 19 | AU24: =NOCH!AU24 -> 152
A25: 13 | B25: 16265 | C25: Толстиков А.В. | D25: слес-рем | F25: А | G25: 8 | H25: 8 | I25: 8 | J25: 8 | AJ25: =IF(RSCH!AJ25=0,"",RSCH!AJ25) | AK25: =IF(RSCH!AK25=0,"",RSCH!AK25) | AL25: =IF(RSCH!AL25=0,"",RSCH!AL25) | AM25: =IF(RSCH!AM25=0,"",RSCH!AM25) | AN25: =IF(RSCH!AN25=0,"",RSCH!AN25) | AO25: =IF(RSCH!AO25=0,"",RSCH!AO25) | AP25: =IF(NOCH!AP25=0,"",NOCH!AP25) | AQ25: =IF(AS25="","",IF((AS25-AU25)>0,AS25-AU25,"")) | AR25: =IF(RSCH!AR25=0,"",RSCH!AR25) -> 4 | AS25: =IF(RSCH!AS25=0,"",RSCH!AS25) -> 32 | AT25: =NOCH!AT25 -> 19 | AU25: =NOCH!AU25 -> 152
A26: 14 | B26: 83322 | C26: Федюшкин А.А. | D26: эл/мех | F26: 8 | G26: 8 | H26: 8 | I26: 8 | J26: 8 | K26: 7 | L26: 7 | AJ26: =IF(RSCH!AJ26=0,"",RSCH!AJ26) | AK26: =IF(RSCH!AK26=0,"",RSCH!AK26) | AL26: =IF(RSCH!AL26=0,"",RSCH!AL26) | AM26: =IF(RSCH!AM26=0,"",RSCH!AM26) | AN26: =IF(RSCH!AN26=0,"",RSCH!AN26) | AO26: =IF(RSCH!AO26=0,"",RSCH!AO26) -> 14 | AP26: =IF(NOCH!AP26=0,"",NOCH!AP26) | AQ26: =IF(AS26="","",IF((AS26-AU26)>0,AS26-AU26,"")) | AR26: =IF(RSCH!AR26=0,"",RSCH!AR26) -> 7 | AS26: =IF(RSCH!AS26=0,"",RSCH!AS26) -> 54 | AT26: =NOCH!AT26 -> 19 | AU26: =NOCH!AU26 -> 152
A27: 15 | B27: 63189 | C27: Харьковский М.В. | D27: гл.мех | F27: 8 | G27: 8 | H27: 8 | I27: 8 | J27: 8 | AJ27: =IF(RSCH!AJ27=0,"",RSCH!AJ27) | AK27: =IF(RSCH!AK27=0,"",RSCH!AK27) | AL27: =IF(RSCH!AL27=0,"",RSCH!AL27) | AM27: =IF(RSCH!AM27=0,"",RSCH!AM27) | AN27: =IF(RSCH!AN27=0,"",RSCH!AN27) | AO27: =IF(RSCH!AO27=0,"",RSCH!AO27) | AP27: =IF(NOCH!AP27=0,"",NOCH!AP27) | AQ27: =IF(AS27="","",IF((AS27-AU27)>0,AS27-AU27,"")) | AR27: =IF(RSCH!AR27=0,"",RSCH!AR27) -> 5 | AS27: =IF(RSCH!AS27=0,"",RSCH!AS27) -> 40 | AT27: =NOCH!AT27 -> 19 | AU27: =NOCH!AU27 -> 152
A28: 16 | B28: 12368 | C28: Якушев И.А. | D28: механик | F28: 8 | G28: 8 | H28: 8 | I28: 8 | J28: 8 | AJ28: =IF(RSCH!AJ28=0,"",RSCH!AJ28) | AK28: =IF(RSCH!AK28=0,"",RSCH!AK28) | AL28: =IF(RSCH!AL28=0,"",RSCH!AL28) | AM28: =IF(RSCH!AM28=0,"",RSCH!AM28) | AN28: =IF(RSCH!AN28=0,"",RSCH!AN28) | AO28: =IF(RSCH!AO28=0,"",RSCH!AO28) | AP28: =IF(NOCH!AP28=0,"",NOCH!AP28) | AQ28: =IF(AS28="","",IF((AS28-AU28)>0,AS28-AU28,"")) | AR28: =IF(RSCH!AR28=0,"",RSCH!AR28) -> 5 | AS28: =IF(RSCH!AS28=0,"",RSCH!AS28) -> 40 | AT28: =NOCH!AT28 -> 19 | AU28: =NOCH!AU28 -> 152
A29: 17 | B29: 12512 | C29: Столповский А.В. | D29: механик | F29: 8 | G29: 8 | H29: 8 | I29: 8 | J29: 8 | AJ29: =IF(RSCH!AJ29=0,"",RSCH!AJ29) | AK29: =IF(RSCH!AK29=0,"",RSCH!AK29) | AL29: =IF(RSCH!AL29=0,"",RSCH!AL29) | AM29: =IF(RSCH!AM29=0,"",RSCH!AM29) | AN29: =IF(RSCH!AN29=0,"",RSCH!AN29) | AO29: =IF(RSCH!AO29=0,"",RSCH!AO29) | AP29: =IF(NOCH!AP29=0,"",NOCH!AP29) | AQ29: =IF(AS29="","",IF((AS29-AU29)>0,AS29-AU29,"")) | AR29: =IF(RSCH!AR29=0,"",RSCH!AR29) -> 5 | AS29: =IF(RSCH!AS29=0,"",RSCH!AS29) -> 40 | AT29: =NOCH!AT29 -> 19 | AU29: =NOCH!AU29 -> 152
B30: ООО Стимул | AJ30: =IF(RSCH!AJ30=0,"",RSCH!AJ30) | AK30: =IF(RSCH!AK30=0,"",RSCH!AK30) | AL30: =IF(RSCH!AL30=0,"",RSCH!AL30) | AM30: =IF(RSCH!AM30=0,"",RSCH!AM30) | AN30: =IF(RSCH!AN30=0,"",RSCH!AN30) | AO30: =IF(RSCH!AO30=0,"",RSCH!AO30) | AP30: =IF(NOCH!AP30=0,"",NOCH!AP30) | AQ30: =IF(AS30="","",IF((AS30-AU30)>0,AS30-AU30,"")) | AR30: =IF(RSCH!AR30=0,"",RSCH!AR30) | AS30: =IF(RSCH!AS30=0,"",RSCH!AS30) | AT30: =NOCH!AT30 | AU30: =NOCH!AU30
A31: 18 | B31: 39962 | C31: Климов Е.Н. | D31: эл/мех | F31: 8 | G31: 8 | H31: 4 | I31: 8 | J31: 8 | AJ31: =IF(RSCH!AJ31=0,"",RSCH!AJ31) | AK31: =IF(RSCH!AK31=0,"",RSCH!AK31) | AL31: =IF(RSCH!AL31=0,"",RSCH!AL31) | AM31: =IF(RSCH!AM31=0,"",RSCH!AM31) | AN31: =IF(RSCH!AN31=0,"",RSCH!AN31) | AO31: =IF(RSCH!AO31=0,"",RSCH!AO31) | AP31: =IF(NOCH!AP31=0,"",NOCH!AP31) | AQ31: =IF(AS31="","",IF((AS31-AU31)>0,AS31-AU31,"")) | AR31: =IF(RSCH!AR31=0,"",RSCH!AR31) -> 5 | AS31: =IF(RSCH!AS31=0,"",RSCH!AS31) -> 36 | AT31: =NOCH!AT31 -> 19 | AU31: =NOCH!AU31 -> 152
A32: 19 | B32: 85743 | C32: Рудиков Д.А. | D32: слес-рем | F32: 8 | G32: 8 | H32: 8 | I32: 8 | J32: 8 | AJ32: =IF(RSCH!AJ32=0,"",RSCH!AJ32) | AK32: =IF(RSCH!AK32=0,"",RSCH!AK32) | AL32: =IF(RSCH!AL32=0,"",RSCH!AL32) | AM32: =IF(RSCH!AM32=0,"",RSCH!AM32) | AN32: =IF(RSCH!AN32=0,"",RSCH!AN32) | AO32: =IF(RSCH!AO32=0,"",RSCH!AO32) | AP32: =IF(NOCH!AP32=0,"",NOCH!AP32) | AQ32: =IF(AS32="","",IF((AS32-AU32)>0,AS32-AU32,"")) | AR32: =IF(RSCH!AR32=0,"",RSCH!AR32) -> 5 | AS32: =IF(RSCH!AS32=0,"",RSCH!AS32) -> 40 | AT32: =NOCH!AT32 -> 19 | AU32: =NOCH!AU32 -> 152
AJ33: =IF(RSCH!AJ33=0,"",RSCH!AJ33) | AK33: =IF(RSCH!AK33=0,"",RSCH!AK33) | AL33: =IF(RSCH!AL33=0,"",RSCH!AL33) | AM33: =IF(RSCH!AM33=0,"",RSCH!AM33) | AN33: =IF(RSCH!AN33=0,"",RSCH!AN33) | AO33: =IF(RSCH!AO33=0,"",RSCH!AO33) | AP33: =IF(NOCH!AP33=0,"",NOCH!AP33) | AQ33: =IF(AS33="","",IF((AS33-AU33)>0,AS33-AU33,"")) | AR33: =IF(RSCH!AR33=0,"",RSCH!AR33) | AS33: =IF(RSCH!AS33=0,"",RSCH!AS33) | AT33: =NOCH!AT33 | AU33: =NOCH!AU33
AJ34: =IF(RSCH!AJ34=0,"",RSCH!AJ34) | AK34: =IF(RSCH!AK34=0,"",RSCH!AK34) | AL34: =IF(RSCH!AL34=0,"",RSCH!AL34) | AM34: =IF(RSCH!AM34=0,"",RSCH!AM34) | AN34: =IF(RSCH!AN34=0,"",RSCH!AN34) | AO34: =IF(RSCH!AO34=0,"",RSCH!AO34) | AP34: =IF(NOCH!AP34=0,"",NOCH!AP34) | AQ34: =IF(AS34="","",IF((AS34-AU34)>0,AS34-AU34,"")) | AR34: =IF(RSCH!AR34=0,"",RSCH!AR34) | AS34: =IF(RSCH!AS34=0,"",RSCH!AS34) | AT34: =NOCH!AT34 | AU34: =NOCH!AU34
AJ35: =IF(RSCH!AJ35=0,"",RSCH!AJ35) | AK35: =IF(RSCH!AK35=0,"",RSCH!AK35) | AL35: =IF(RSCH!AL35=0,"",RSCH!AL35) | AM35: =IF(RSCH!AM35=0,"",RSCH!AM35) | AN35: =IF(RSCH!AN35=0,"",RSCH!AN35) | AO35: =IF(RSCH!AO35=0,"",RSCH!AO35) | AP35: =IF(NOCH!AP35=0,"",NOCH!AP35) | AQ35: =IF(AS35="","",IF((AS35-AU35)>0,AS35-AU35,"")) | AR35: =IF(RSCH!AR35=0,"",RSCH!AR35) | AS35: =IF(RSCH!AS35=0,"",RSCH!AS35) | AT35: =NOCH!AT35 | AU35: =NOCH!AU35
AJ36: =IF(RSCH!AJ36=0,"",RSCH!AJ36) | AK36: =IF(RSCH!AK36=0,"",RSCH!AK36) | AL36: =IF(RSCH!AL36=0,"",RSCH!AL36) | AM36: =IF(RSCH!AM36=0,"",RSCH!AM36) | AN36: =IF(RSCH!AN36=0,"",RSCH!AN36) | AO36: =IF(RSCH!AO36=0,"",RSCH!AO36) | AP36: =IF(NOCH!AP36=0,"",NOCH!AP36) | AQ36: =IF(AS36="","",IF((AS36-AU36)>0,AS36-AU36,"")) | AR36: =IF(RSCH!AR36=0,"",RSCH!AR36) | AS36: =IF(RSCH!AS36=0,"",RSCH!AS36) | AT36: =NOCH!AT36 | AU36: =NOCH!AU36
AJ37: =IF(RSCH!AJ37=0,"",RSCH!AJ37) | AK37: =IF(RSCH!AK37=0,"",RSCH!AK37) | AL37: =IF(RSCH!AL37=0,"",RSCH!AL37) | AM37: =IF(RSCH!AM37=0,"",RSCH!AM37) | AN37: =IF(RSCH!AN37=0,"",RSCH!AN37) | AO37: =IF(RSCH!AO37=0,"",RSCH!AO37) | AP37: =IF(NOCH!AP37=0,"",NOCH!AP37) | AQ37: =IF(AS37="","",IF((AS37-AU37)>0,AS37-AU37,"")) | AR37: =IF(RSCH!AR37=0,"",RSCH!AR37) | AS37: =IF(RSCH!AS37=0,"",RSCH!AS37) | AT37: =NOCH!AT37 | AU37: =NOCH!AU37
AJ38: =IF(RSCH!AJ38=0,"",RSCH!AJ38) | AK38: =IF(RSCH!AK38=0,"",RSCH!AK38) | AL38: =IF(RSCH!AL38=0,"",RSCH!AL38) | AM38: =IF(RSCH!AM38=0,"",RSCH!AM38) | AN38: =IF(RSCH!AN38=0,"",RSCH!AN38) | AO38: =IF(RSCH!AO38=0,"",RSCH!AO38) | AP38: =IF(NOCH!AP38=0,"",NOCH!AP38) | AQ38: =IF(AS38="","",IF((AS38-AU38)>0,AS38-AU38,"")) | AR38: =IF(RSCH!AR38=0,"",RSCH!AR38) | AS38: =IF(RSCH!AS38=0,"",RSCH!AS38) | AT38: =NOCH!AT38 | AU38: =NOCH!AU38
AJ39: =IF(RSCH!AJ39=0,"",RSCH!AJ39) | AK39: =IF(RSCH!AK39=0,"",RSCH!AK39) | AL39: =IF(RSCH!AL39=0,"",RSCH!AL39) | AM39: =IF(RSCH!AM39=0,"",RSCH!AM39) | AN39: =IF(RSCH!AN39=0,"",RSCH!AN39) | AO39: =IF(RSCH!AO39=0,"",RSCH!AO39) | AP39: =IF(NOCH!AP39=0,"",NOCH!AP39) | AQ39: =IF(AS39="","",IF((AS39-AU39)>0,AS39-AU39,"")) | AR39: =IF(RSCH!AR39=0,"",RSCH!AR39) | AS39: =IF(RSCH!AS39=0,"",RSCH!AS39) | AT39: =NOCH!AT39 | AU39: =NOCH!AU39
E40: ВС | F40: ПН | G40: ВТ | H40: СР | I40: ЧТ | J40: ПТ | K40: СБ | L40: ВС | M40: ПН | N40: ВТ | O40: СР | P40: ЧТ | Q40: ПТ | R40: СБ | S40: ВС | T40: ПН | U40: ВТ | V40: СР | W40: ЧТ | X40: ПТ | Y40: СБ | Z40: ВС | AA40: ПН | AB40: ВТ | AC40: СР | AD40: ЧТ | AE40: ПТ | AF40: СБ | AG40: ВС | AH40: ПН | AI40: ВТ | AM40: Итого дней | AR40: =SUM(AR13:AR34) -> 89 | AT40: =SUM(AT13:AT34) -> 323
...

Sheet RSCH
C1: АО Риф, ООО Стимул | AU1: Унифицированная форма № Т-13
C2: наименование организации | AU2: Утверждена постановлением Госкомстата РФ
C3: ПК №250 | X3: Принятые | AU3: от 5 января 2004 г. N 1
C4: наименование структурного подразделения
A5: ТАБЕЛЬ | AU5: 14
A6: учета использования рабочего времени
A7: =CONCATENATE("за ",данные!A1," месяц ",данные!B1) -> за февраль месяц 2026 года.
A8: № п/п | B8: Табельный номер | C8: Фамилия, инициалы, должность (специальность, профессия) | D8: Профессия | E8: Отметки о явках и неявках на работу по числам месяца | AJ8: Отработано за
E9: 01 | F9: 02 | G9: 03 | H9: 04 | I9: 05 | J9: 06 | K9: 07 | L9: 08 | M9: 09 | N9: 10 | O9: 11 | P9: 12 | Q9: 13 | R9: 14 | S9: 15 | T9: 16 | U9: 17 | V9: 18 | W9: 19 | X9: 20 | Y9: 21 | Z9: 22 | AA9: 23 | AB9: 24 | AC9: 25 | AD9: 26 | AE9: 27 | AF9: 28 | AG9: 29 | AH9: 30 | AI9: 31 | AJ9: Месяц | AR9: Отработано | AT9: Всего
AJ10: командиров. | AK10: прогул | AL10: боль-нич- ный | AM10: отпуск | AN10: адм. отп | AO10: празд вы- ходн | AP10: ночн. | AQ10: пере-работ- ка | AR10: дней | AS10: часов | AT10: дней | AU10: часов
A11: 1 | C11: 2 | D11: 3 | E11: 4 | AJ11: 5 | AK11: 6 | AL11: 7 | AM11: 8 | AN11: 9 | AO11: 10 | AP11: 11 | AQ11: 12 | AR11: 13 | AS11: 14 | AT11: 15 | AU11: 16
B12: АО Риф
A13: 1 | B13: 83727 | C13: Горбуненко Ф.Ф. | D13: слес-рем | E13: =IF(OR(Main!E13="",Main!E13=0),"",INDEX($E$46:$AB$47,2,MATCH(Main!E13,$E$46:$AB$46,0))) | F13: =IF(OR(Main!F13="",Main!F13=0),"",INDEX($E$46:$AB$47,2,MATCH(Main!F13,$E$46:$AB$46,0))) -> 8 | G13: =IF(OR(Main!G13="",Main!G13=0),"",INDEX($E$46:$AB$47,2,MATCH(Main!G13,$E$46:$AB$46,0))) -> 4 | H13: =IF(OR(Main!H13="",Main!H13=0,Main!E13="А"),"",INDEX($E$46:$AB$47,2,MATCH(Main!H13,$E$46:$AB$46,0))) -> 0 | I13: =IF(OR(Main!I13="",Main!I13=0),"",INDEX($E$46:$AB$47,2,MATCH(Main!I13,$E$46:$AB$46,0))) -> 8 | J13: =IF(OR(Main!J13="",Main!J13=0),"",INDEX($E$46:$AB$47,2,MATCH(Main!J13,$E$46:$AB$46,0))) -> 8 | K13: =IF(OR(Main!K13="",Main!K13=0),"",INDEX($E$46:$AB$47,2,MATCH(Main!K13,$E$46:$AB$46,0))) -> 7 | L13: =IF(OR(Main!L13="",Main!L13=0),"",INDEX($E$46:$AB$47,2,MATCH(Main!L13,$E$46:$AB$46,0))) -> 7 | M13: =IF(OR(Main!M13="",Main!M13=0),"",INDEX($E$46:$AB$47,2,MATCH(Main!M13,$E$46:$AB$46,0))) | N13: =IF(OR(Main!N13="",Main!N13=0),"",INDEX($E$46:$AB$47,2,MATCH(Main!N13,$E$46:$AB$46,0))) | O13: =IF(OR(Main!O13="",Main!O13=0),"",INDEX($E$46:$AB$47,2,MATCH(Main!O13,$E$46:$AB$46,0))) | P13: =IF(OR(Main!P13="",Main!P13=0),"",INDEX($E$46:$AB$47,2,MATCH(Main!P13,$E$46:$AB$46,0))) | ... AI13: =IF(OR(Main!AI13="",Main!AI13=0),"",INDEX($E$46:$AB$47,2,MATCH(Main!AI13,$E$46:$AB$46,0))) | AJ13: =COUNTIF(Main!E13:'Main'!AI13,"К") -> 0 | AK13: =COUNTIF(Main!E13:'Main'!AI13,"П") -> 0 | AL13: =COUNTIF(Main!E13:'Main'!AI13,"Б") -> 0 | AM13: =COUNTIF(Main!E13:'Main'!AI13,"О") -> 0 | AN13: =COUNTIF(Main!E13:'Main'!AI13,"АО") -> 0 | AO13: =SUMIF($E$43:$AI$43,"В",Main!E13:'Main'!AI13) -> 14 | AR13: =COUNTIF(E13:AI13,">0") -> 6 | AS13: =SUM(E13:AI13) -> 42 | AT13: 19 | AU13: 152
A14: 2 | B14: 89046 | C14: Дулов С.Д. | D14: слес-рем | E14: =IF(Main!E14="","",INDEX($E$46:$AB$47,2,MATCH(Main!E14,$E$46:$AB$46,0))) | F14: =IF(Main!F14="","",INDEX($E$46:$AB$47,2,MATCH(Main!F14,$E$46:$AB$46,0))) -> 8 | G14: =IF(Main!G14="","",INDEX($E$46:$AB$47,2,MATCH(Main!G14,$E$46:$AB$46,0))) -> 8 | H14: =IF(Main!H14="","",INDEX($E$46:$AB$47,2,MATCH(Main!H14,$E$46:$AB$46,0))) -> 8 | I14: =IF(Main!I14="","",INDEX($E$46:$AB$47,2,MATCH(Main!I14,$E$46:$AB$46,0))) -> 8 | J14: =IF(Main!J14="","",INDEX($E$46:$AB$47,2,MATCH(Main!J14,$E$46:$AB$46,0))) -> 8 | K14: =IF(Main!K14="","",INDEX($E$46:$AB$47,2,MATCH(Main!K14,$E$46:$AB$46,0))) -> 7 | L14: =IF(Main!L14="","",INDEX($E$46:$AB$47,2,MATCH(Main!L14,$E$46:$AB$46,0))) | ... AI14: =IF(Main!AI14="","",INDEX($E$46:$AB$47,2,MATCH(Main!AI14,$E$46:$AB$46,0))) | AJ14: =COUNTIF(Main!E14:'Main'!AI14,"К") -> 0 | AK14: =COUNTIF(Main!E14:'Main'!AI14,"П") -> 0 | AL14: =COUNTIF(Main!E14:'Main'!AI14,"Б") -> 0 | AM14: =COUNTIF(Main!E14:'Main'!AI14,"О") -> 0 | AN14: =COUNTIF(Main!E14:'Main'!AI14,"АО") -> 0 | AO14: =SUMIF($E$43:$AI$43,"В",Main!E14:'Main'!AI14) -> 7 | AR14: =COUNTIF(E14:AI14,">0") -> 6 | AS14: =SUM(E14:AI14) -> 47 | AT14: 19 | AU14: 152
A15: 3 | B15: 31205 | C15: Карпенко А.Г. | D15: слес-рем | E15: =IF(Main!E15="","",INDEX($E$46:$AB$47,2,MATCH(Main!E15,$E$46:$AB$46,0))) -> 0 | F15: =IF(Main!F15="","",INDEX($E$46:$AB$47,2,MATCH(Main!F15,$E$46:$AB$46,0))) -> 0 | G15: =IF(Main!G15="","",INDEX($E$46:$AB$47,2,MATCH(Main!G15,$E$46:$AB$46,0))) -> 0 | H15: =IF(Main!H15="","",INDEX($E$46:$AB$47,2,MATCH(Main!H15,$E$46:$AB$46,0))) -> 0 | I15: =IF(Main!I15="","",INDEX($E$46:$AB$47,2,MATCH(Main!I15,$E$46:$AB$46,0))) -> 0 | J15: =IF(Main!J15="","",INDEX($E$46:$AB$47,2,MATCH(Main!J15,$E$46:$AB$46,0))) -> 0 | K15: =IF(Main!K15="","",INDEX($E$46:$AB$47,2,MATCH(Main!K15,$E$46:$AB$46,0))) -> 0 | L15: =IF(Main!L15="","",INDEX($E$46:$AB$47,2,MATCH(Main!L15,$E$46:$AB$46,0))) -> 0 | ... AI15: =IF(Main!AI15="","",INDEX($E$46:$AB$47,2,MATCH(Main!AI15,$E$46:$AB$46,0))) | AJ15: =COUNTIF(Main!E15:'Main'!AI15,"К") -> 0 | AK15: =COUNTIF(Main!E15:'Main'!AI15,"П") -> 0 | AL15: =COUNTIF(Main!E15:'Main'!AI15,"Б") -> 0 | AM15: =COUNTIF(Main!E15:'Main'!AI15,"О") -> 8 | AN15: =COUNTIF(Main!E15:'Main'!AI15,"АО") -> 0 | AO15: =SUMIF($E$43:$AI$43,"В",Main!E15:'Main'!AI15) -> 0 | AR15: =COUNTIF(E15:AI15,">0") -> 0 | AS15: =SUM(E15:AI15) -> 0 | AT15: 19 | AU15: 152
A16: 4 | B16: 83448 | C16: Колодный С.С. | D16: эл/мех | E16: =IF(Main!E16="","",INDEX($E$46:$AB$47,2,MATCH(Main!E16,$E$46:$AB$46,0))) -> 7 | F16: =IF(Main!F16="","",INDEX($E$46:$AB$47,2,MATCH(Main!F16,$E$46:$AB$46,0))) -> 0 | G16: =IF(Main!G16="","",INDEX($E$46:$AB$47,2,MATCH(Main!G16,$E$46:$AB$46,0))) -> 8 | H16: =IF(Main!H16="","",INDEX($E$46:$AB$47,2,MATCH(Main!H16,$E$46:$AB$46,0))) -> 8 | I16: =IF(Main!I16="","",INDEX($E$46:$AB$47,2,MATCH(Main!I16,$E$46:$AB$46,0))) -> 8 | J16: =IF(Main!J16="","",INDEX($E$46:$AB$47,2,MATCH(Main!J16,$E$46:$AB$46,0))) -> 8 | K16: =IF(Main!K16="","",INDEX($E$46:$AB$47,2,MATCH(Main!K16,$E$46:$AB$46,0))) | L16: =IF(Main!L16="","",INDEX($E$46:$AB$47,2,MATCH(Main!L16,$E$46:$AB$46,0))) | ... AI16: =IF(Main!AI16="","",INDEX($E$46:$AB$47,2,MATCH(Main!AI16,$E$46:$AB$46,0))) | AJ16: =COUNTIF(Main!E16:'Main'!AI16,"К") -> 0 | AK16: =COUNTIF(Main!E16:'Main'!AI16,"П") -> 0 | AL16: =COUNTIF(Main!E16:'Main'!AI16,"Б") -> 0 | AM16: =COUNTIF(Main!E16:'Main'!AI16,"О") -> 0 | AN16: =COUNTIF(Main!E16:'Main'!AI16,"АО") -> 0 | AO16: =SUMIF($E$43:$AI$43,"В",Main!E16:'Main'!AI16) -> 7 | AR16: =COUNTIF(E16:AI16,">0") -> 5 | AS16: =SUM(E16:AI16) -> 39 | AT16: 19 | AU16: 152
A17: 5 | B17: 21782 | C17: Котов О.А. | D17: слес-рем | E17: =IF(Main!E17="","",INDEX($E$46:$AB$47,2,MATCH(Main!E17,$E$46:$AB$46,0))) -> 7 | F17: =IF(Main!F17="","",INDEX($E$46:$AB$47,2,MATCH(Main!F17,$E$46:$AB$46,0))) -> 8 | G17: =IF(Main!G17="","",INDEX($E$46:$AB$47,2,MATCH(Main!G17,$E$46:$AB$46,0))) -> 8 | H17: =IF(Main!H17="","",INDEX($E$46:$AB$47,2,MATCH(Main!H17,$E$46:$AB$46,0))) -> 8 | I17: =IF(Main!I17="","",INDEX($E$46:$AB$47,2,MATCH(Main!I17,$E$46:$AB$46,0))) -> 8 | J17: =IF(Main!J17="","",INDEX($E$46:$AB$47,2,MATCH(Main!J17,$E$46:$AB$46,0))) -> 8 | K17: =IF(Main!K17="","",INDEX($E$46:$AB$47,2,MATCH(Main!K17,$E$46:$AB$46,0))) | L17: =IF(Main!L17="","",INDEX($E$46:$AB$47,2,MATCH(Main!L17,$E$46:$AB$46,0))) | ... AI17: =IF(Main!AI17="","",INDEX($E$46:$AB$47,2,MATCH(Main!AI17,$E$46:$AB$46,0))) | AJ17: =COUNTIF(Main!E17:'Main'!AI17,"К") -> 0 | AK17: =COUNTIF(Main!E17:'Main'!AI17,"П") -> 0 | AL17: =COUNTIF(Main!E17:'Main'!AI17,"Б") -> 0 | AM17: =COUNTIF(Main!E17:'Main'!AI17,"О") -> 0 | AN17: =COUNTIF(Main!E17:'Main'!AI17,"АО") -> 0 | AO17: =SUMIF($E$43:$AI$43,"В",Main!E17:'Main'!AI17) -> 7 | AR17: =COUNTIF(E17:AI17,">0") -> 6 | AS17: =SUM(E17:AI17) -> 47 | AT17: 19 | AU17: 152
A18: 6 | B18: 90072 | C18: Кривоконев В.И. | D18: слес-рем | E18: =IF(Main!E18="","",INDEX($E$46:$AB$47,2,MATCH(Main!E18,$E$46:$AB$46,0))) | F18: =IF(Main!F18="","",INDEX($E$46:$AB$47,2,MATCH(Main!F18,$E$46:$AB$46,0))) -> 8 | G18: =IF(Main!G18="","",INDEX($E$46:$AB$47,2,MATCH(Main!G18,$E$46:$AB$46,0))) -> 8 | H18: =IF(Main!H18="","",INDEX($E$46:$AB$47,2,MATCH(Main!H18,$E$46:$AB$46,0))) -> 8 | I18: =IF(Main!I18="","",INDEX($E$46:$AB$47,2,MATCH(Main!I18,$E$46:$AB$46,0))) -> 8 | J18: =IF(Main!J18="","",INDEX($E$46:$AB$47,2,MATCH(Main!J18,$E$46:$AB$46,0))) -> 8 | K18: =IF(Main!K18="","",INDEX($E$46:$AB$47,2,MATCH(Main!K18,$E$46:$AB$46,0))) | L18: =IF(Main!L18="","",INDEX($E$46:$AB$47,2,MATCH(Main!L18,$E$46:$AB$46,0))) | ... AI18: =IF(Main!AI18="","",INDEX($E$46:$AB$47,2,MATCH(Main!AI18,$E$46:$AB$46,0))) | AJ18: =COUNTIF(Main!E18:'Main'!AI18,"К") -> 0 | AK18: =COUNTIF(Main!E18:'Main'!AI18,"П") -> 0 | AL18: =COUNTIF(Main!E18:'Main'!AI18,"Б") -> 0 | AM18: =COUNTIF(Main!E18:'Main'!AI18,"О") -> 0 | AN18: =COUNTIF(Main!E18:'Main'!AI18,"АО") -> 0 | AO18: =SUMIF($E$43:$AI$43,"В",Main!E18:'Main'!AI18) -> 0 | AR18: =COUNTIF(E18:AI18,">0") -> 5 | AS18: =SUM(E18:AI18) -> 40 | AT18: 19 | AU18: 152
A19: 7 | B19: 63549 | C19: Лахин В.В. | D19: слес-рем | E19: =IF(Main!E19="","",INDEX($E$46:$AB$47,2,MATCH(Main!E19,$E$46:$AB$46,0))) | F19: =IF(Main!F19="","",INDEX($E$46:$AB$47,2,MATCH(Main!F19,$E$46:$AB$46,0))) -> 8 | G19: =IF(Main!G19="","",INDEX($E$46:$AB$47,2,MATCH(Main!G19,$E$46:$AB$46,0))) -> 8 | H19: =IF(Main!H19="","",INDEX($E$46:$AB$47,2,MATCH(Main!H19,$E$46:$AB$46,0))) -> 8 | I19: =IF(Main!I19="","",INDEX($E$46:$AB$47,2,MATCH(Main!I19,$E$46:$AB$46,0))) -> 8 | J19: =IF(Main!J19="","",INDEX($E$46:$AB$47,2,MATCH(Main!J19,$E$46:$AB$46,0))) -> 8 | K19: =IF(Main!K19="","",INDEX($E$46:$AB$47,2,MATCH(Main!K19,$E$46:$AB$46,0))) | L19: =IF(Main!L19="","",INDEX($E$46:$AB$47,2,MATCH(Main!L19,$E$46:$AB$46,0))) | ... AI19: =IF(Main!AI19="","",INDEX($E$46:$AB$47,2,MATCH(Main!AI19,$E$46:$AB$46,0))) | AJ19: =COUNTIF(Main!E19:'Main'!AI19,"К") -> 0 | AK19: =COUNTIF(Main!E19:'Main'!AI19,"П") -> 0 | AL19: =COUNTIF(Main!E19:'Main'!AI19,"Б") -> 0 | AM19: =COUNTIF(Main!E19:'Main'!AI19,"О") -> 0 | AN19: =COUNTIF(Main!E19:'Main'!AI19,"АО") -> 0 | AO19: =SUMIF($E$43:$AI$43,"В",Main!E19:'Main'!AI19) -> 0 | AR19: =COUNTIF(E19:AI19,">0") -> 5 | AS19: =SUM(E19:AI19) -> 40 | AT19: 19 | AU19: 152
A20: 8 | B20: 12377 | C20: Лахин С.Н. | D20: слес-рем | E20: =IF(Main!E20="","",INDEX($E$46:$AB$47,2,MATCH(Main!E20,$E$46:$AB$46,0))) | F20: =IF(Main!F20="","",INDEX($E$46:$AB$47,2,MATCH(Main!F20,$E$46:$AB$46,0))) -> 8 | G20: =IF(Main!G20="","",INDEX($E$46:$AB$47,2,MATCH(Main!G20,$E$46:$AB$46,0))) -> 8 | H20: =IF(Main!H20="","",INDEX($E$46:$AB$47,2,MATCH(Main!H20,$E$46:$AB$46,0))) -> 8 | I20: =IF(Main!I20="","",INDEX($E$46:$AB$47,2,MATCH(Main!I20,$E$46:$AB$46,0))) -> 8 | J20: =IF(Main!J20="","",INDEX($E$46:$AB$47,2,MATCH(Main!J20,$E$46:$AB$46,0))) -> 8 | K20: =IF(Main!K20="","",INDEX($E$46:$AB$47,2,MATCH(Main!K20,$E$46:$AB$46,0))) | L20: =IF(Main!L20="","",INDEX($E$46:$AB$47,2,MATCH(Main!L20,$E$46:$AB$46,0))) | ... AI20: =IF(Main!AI20="","",INDEX($E$46:$AB$47,2,MATCH(Main!AI20,$E$46:$AB$46,0))) | AJ20: =COUNTIF(Main!E20:'Main'!AI20,"К") -> 0 | AK20: =COUNTIF(Main!E20:'Main'!AI20,"П") -> 0 | AL20: =COUNTIF(Main!E20:'Main'!AI20,"Б") -> 0 | AM20: =COUNTIF(Main!E20:'Main'!AI20,"О") -> 0 | AN20: =COUNTIF(Main!E20:'Main'!AI20,"АО") -> 0 | AO20: =SUMIF($E$43:$AI$43,"В",Main!E20:'Main'!AI20) -> 0 | AR20: =COUNTIF(E20:AI20,">0") -> 5 | AS20: =SUM(E20:AI20) -> 40 | AT20: 19 | AU20: 152
A21: 9 | B21: 63558 | C21: Миньков А.А. | D21: слес-рем | E21: =IF(Main!E21="","",INDEX($E$46:$AB$47,2,MATCH(Main!E21,$E$46:$AB$46,0))) -> 0 | F21: =IF(Main!F21="","",INDEX($E$46:$AB$47,2,MATCH(Main!F21,$E$46:$AB$46,0))) -> 0 | G21: =IF(Main!G21="","",INDEX($E$46:$AB$47,2,MATCH(Main!G21,$E$46:$AB$46,0))) -> 0 | H21: =IF(Main!H21="","",INDEX($E$46:$AB$47,2,MATCH(Main!H21,$E$46:$AB$46,0))) -> 0 | I21: =IF(Main!I21="","",INDEX($E$46:$AB$47,2,MATCH(Main!I21,$E$46:$AB$46,0))) -> 0 | J21: =IF(Main!J21="","",INDEX($E$46:$AB$47,2,MATCH(Main!J21,$E$46:$AB$46,0))) -> 0 | K21: =IF(Main!K21="","",INDEX($E$46:$AB$47,2,MATCH(Main!K21,$E$46:$AB$46,0))) -> 0 | L21: =IF(Main!L21="","",INDEX($E$46:$AB$47,2,MATCH(Main!L21,$E$46:$AB$46,0))) -> 0 | ... AI21: =IF(Main!AI21="","",INDEX($E$46:$AB$47,2,MATCH(Main!AI21,$E$46:$AB$46,0))) | AJ21: =COUNTIF(Main!E21:'Main'!AI21,"К") -> 0 | AK21: =COUNTIF(Main!E21:'Main'!AI21,"П") -> 0 | AL21: =COUNTIF(Main!E21:'Main'!AI21,"Б") -> 0 | AM21: =COUNTIF(Main!E21:'Main'!AI21,"О") -> 8 | AN21: =COUNTIF(Main!E21:'Main'!AI21,"АО") -> 0 | AO21: =SUMIF($E$43:$AI$43,"В",Main!E21:'Main'!AI21) -> 0 | AR21: =COUNTIF(E21:AI21,">0") -> 0 | AS21: =SUM(E21:AI21) -> 0 | AT21: 19 | AU21: 152
A22: 10 | B22: 31178 | C22: Никонов Н.А. | D22: слес-рем | E22: =IF(Main!E22="","",INDEX($E$46:$AB$47,2,MATCH(Main!E22,$E$46:$AB$46,0))) | F22: =IF(Main!F22="","",INDEX($E$46:$AB$47,2,MATCH(Main!F22,$E$46:$AB$46,0))) -> 8 | G22: =IF(Main!G22="","",INDEX($E$46:$AB$47,2,MATCH(Main!G22,$E$46:$AB$46,0))) -> 8 | H22: =IF(Main!H22="","",INDEX($E$46:$AB$47,2,MATCH(Main!H22,$E$46:$AB$46,0))) -> 8 | I22: =IF(Main!I22="","",INDEX($E$46:$AB$47,2,MATCH(Main!I22,$E$46:$AB$46,0))) -> 8 | J22: =IF(Main!J22="","",INDEX($E$46:$AB$47,2,MATCH(Main!J22,$E$46:$AB$46,0))) -> 8 | K22: =IF(Main!K22="","",INDEX($E$46:$AB$47,2,MATCH(Main!K22,$E$46:$AB$46,0))) | L22: =IF(Main!L22="","",INDEX($E$46:$AB$47,2,MATCH(Main!L22,$E$46:$AB$46,0))) | ... AI22: =IF(Main!AI22="","",INDEX($E$46:$AB$47,2,MATCH(Main!AI22,$E$46:$AB$46,0))) | AJ22: =COUNTIF(Main!E22:'Main'!AI22,"К") -> 0 | AK22: =COUNTIF(Main!E22:'Main'!AI22,"П") -> 0 | AL22: =COUNTIF(Main!E22:'Main'!AI22,"Б") -> 0 | AM22: =COUNTIF(Main!E22:'Main'!AI22,"О") -> 0 | AN22: =COUNTIF(Main!E22:'Main'!AI22,"АО") -> 0 | AO22: =SUMIF($E$43:$AI$43,"В",Main!E22:'Main'!AI22) -> 0 | AR22: =COUNTIF(E22:AI22,">0") -> 5 | AS22: =SUM(E22:AI22) -> 40 | AT22: 19 | AU22: 152
A23: 11 | B23: 21116 | C23: Переверзев А.М. | D23: слес-рем | E23: =IF(Main!E23="","",INDEX($E$46:$AB$47,2,MATCH(Main!E23,$E$46:$AB$46,0))) | F23: =IF(Main!F23="","",INDEX($E$46:$AB$47,2,MATCH(Main!F23,$E$46:$AB$46,0))) -> 8 | G23: =IF(Main!G23="","",INDEX($E$46:$AB$47,2,MATCH(Main!G23,$E$46:$AB$46,0))) -> 8 | H23: =IF(Main!H23="","",INDEX($E$46:$AB$47,2,MATCH(Main!H23,$E$46:$AB$46,0))) -> 8 | I23: =IF(Main!I23="","",INDEX($E$46:$AB$47,2,MATCH(Main!I23,$E$46:$AB$46,0))) -> 8 | J23: =IF(Main!J23="","",INDEX($E$46:$AB$47,2,MATCH(Main!J23,$E$46:$AB$46,0))) -> 8 | K23: =IF(Main!K23="","",INDEX($E$46:$AB$47,2,MATCH(Main!K23,$E$46:$AB$46,0))) | L23: =IF(Main!L23="","",INDEX($E$46:$AB$47,2,MATCH(Main!L23,$E$46:$AB$46,0))) | ... AI23: =IF(Main!AI23="","",INDEX($E$46:$AB$47,2,MATCH(Main!AI23,$E$46:$AB$46,0))) | AJ23: =COUNTIF(Main!E23:'Main'!AI23,"К") -> 0 | AK23: =COUNTIF(Main!E23:'Main'!AI23,"П") -> 0 | AL23: =COUNTIF(Main!E23:'Main'!AI23,"Б") -> 0 | AM23: =COUNTIF(Main!E23:'Main'!AI23,"О") -> 0 | AN23: =COUNTIF(Main!E23:'Main'!AI23,"АО") -> 0 | AO23: =SUMIF($E$43:$AI$43,"В",Main!E23:'Main'!AI23) -> 0 | AR23: =COUNTIF(E23:AI23,">0") -> 5 | AS23: =SUM(E23:AI23) -> 40 | AT23: 19 | AU23: 152
A24: 12 | B24: 66051 | C24: Табалин П.А. | D24: эл/мех | E24: =IF(Main!E24="","",INDEX($E$46:$AB$47,2,MATCH(Main!E24,$E$46:$AB$46,0))) | F24: =IF(Main!F24="","",INDEX($E$46:$AB$47,2,MATCH(Main!F24,$E$46:$AB$46,0))) -> 8 | G24: =IF(Main!G24="","",INDEX($E$46:$AB$47,2,MATCH(Main!G24,$E$46:$AB$46,0))) -> 8 | H24: =IF(Main!H24="","",INDEX($E$46:$AB$47,2,MATCH(Main!H24,$E$46:$AB$46,0))) -> 8 | I24: =IF(Main!I24="","",INDEX($E$46:$AB$47,2,MATCH(Main!I24,$E$46:$AB$46,0))) -> 8 | J24: =IF(Main!J24="","",INDEX($E$46:$AB$47,2,MATCH(Main!J24,$E$46:$AB$46,0))) -> 8 | K24: =IF(Main!K24="","",INDEX($E$46:$AB$47,2,MATCH(Main!K24,$E$46:$AB$46,0))) | L24: =IF(Main!L24="","",INDEX($E$46:$AB$47,2,MATCH(Main!L24,$E$46:$AB$46,0))) | ... AI24: =IF(Main!AI24="","",INDEX($E$46:$AB$47,2,MATCH(Main!AI24,$E$46:$AB$46,0))) | AJ24: =COUNTIF(Main!E24:'Main'!AI24,"К") -> 0 | AK24: =COUNTIF(Main!E24:'Main'!AI24,"П") -> 0 | AL24: =COUNTIF(Main!E24:'Main'!AI24,"Б") -> 0 | AM24: =COUNTIF(Main!E24:'Main'!AI24,"О") -> 0 | AN24: =COUNTIF(Main!E24:'Main'!AI24,"АО") -> 0 | AO24: =SUMIF($E$43:$AI$43,"В",Main!E24:'Main'!AI24) -> 0 | AR24: =COUNTIF(E24:AI24,">0") -> 5 | AS24: =SUM(E24:AI24) -> 40 | AT24: 19 | AU24: 152
A25: 13 | B25: 16265 | C25: Толстиков А.В. | D25: слес-рем | E25: =IF(Main!E25="","",INDEX($E$46:$AB$47,2,MATCH(Main!E25,$E$46:$AB$46,0))) | F25: =IF(Main!F25="","",INDEX($E$46:$AB$47,2,MATCH(Main!F25,$E$46:$AB$46,0))) -> 0 | G25: =IF(Main!G25="","",INDEX($E$46:$AB$47,2,MATCH(Main!G25,$E$46:$AB$46,0))) -> 8 | H25: =IF(Main!H25="","",INDEX($E$46:$AB$47,2,MATCH(Main!H25,$E$46:$AB$46,0))) -> 8 | I25: =IF(Main!I25="","",INDEX($E$46:$AB$47,2,MATCH(Main!I25,$E$46:$AB$46,0))) -> 8 | J25: =IF(Main!J25="","",INDEX($E$46:$AB$47,2,MATCH(Main!J25,$E$46:$AB$46,0))) -> 8 | K25: =IF(Main!K25="","",INDEX($E$46:$AB$47,2,MATCH(Main!K25,$E$46:$AB$46,0))) | L25: =IF(Main!L25="","",INDEX($E$46:$AB$47,2,MATCH(Main!L25,$E$46:$AB$46,0))) | ... AI25: =IF(Main!AI25="","",INDEX($E$46:$AB$47,2,MATCH(Main!AI25,$E$46:$AB$46,0))) | AJ25: =COUNTIF(Main!E25:'Main'!AI25,"К") -> 0 | AK25: =COUNTIF(Main!E25:'Main'!AI25,"П") -> 0 | AL25: =COUNTIF(Main!E25:'Main'!AI25,"Б") -> 0 | AM25: =COUNTIF(Main!E25:'Main'!AI25,"О") -> 0 | AN25: =COUNTIF(Main!E25:'Main'!AI25,"АО") -> 0 | AO25: =SUMIF($E$43:$AI$43,"В",Main!E25:'Main'!AI25) -> 0 | AR25: =COUNTIF(E25:AI25,">0") -> 4 | AS25: =SUM(E25:AI25) -> 32 | AT25: 19 | AU25: 152
... A29: 17 | B29: 12512 | C29: Столповский А.В. | D29: механик | E29: =IF(Main!E29="","",INDEX($E$46:$AB$47,2,MATCH(Main!E29,$E$46:$AB$46,0))) | F29: =IF(Main!F29="","",INDEX($E$46:$AB$47,2,MATCH(Main!F29,$E$46:$AB$46,0))) -> 8 | G29: =IF(Main!G29="","",INDEX($E$46:$AB$47,2,MATCH(Main!G29,$E$46:$AB$46,0))) -> 8 | H29: =IF(Main!H29="","",INDEX($E$46:$AB$47,2,MATCH(Main!H29,$E$46:$AB$46,0))) -> 8 | I29: =IF(Main!I29="","",INDEX($E$46:$AB$47,2,MATCH(Main!I29,$E$46:$AB$46,0))) -> 8 | J29: =IF(Main!J29="","",INDEX($E$46:$AB$47,2,MATCH(Main!J29,$E$46:$AB$46,0))) -> 8 | K29: =IF(Main!K29="","",INDEX($E$46:$AB$47,2,MATCH(Main!K29,$E$46:$AB$46,0))) | L29: =IF(Main!L29="","",INDEX($E$46:$AB$47,2,MATCH(Main!L29,$E$46:$AB$46,0))) | ... AI29: =IF(Main!AI29="","",INDEX($E$46:$AB$47,2,MATCH(Main!AI29,$E$46:$AB$46,0))) | AJ29: =COUNTIF(Main!E29:'Main'!AI29,"К") -> 0 | AK29: =COUNTIF(Main!E29:'Main'!AI29,"П") -> 0 | AL29: =COUNTIF(Main!E29:'Main'!AI29,"Б") -> 0 | AM29: =COUNTIF(Main!E29:'Main'!AI29,"О") -> 0 | AN29: =COUNTIF(Main!E29:'Main'!AI29,"АО") -> 0 | AO29: =SUMIF($E$43:$AI$43,"В",Main!E29:'Main'!AI29) -> 0 | AR29: =COUNTIF(E29:AI29,">0") -> 5 | AS29: =SUM(E29:AI29) -> 40 | AT29: 19 | AU29: 152
B30: ООО Стимул | E30: =IF(Main!E30="","",INDEX($E$46:$AB$47,2,MATCH(Main!E30,$E$46:$AB$46,0))) | F30: =IF(Main!F30="","",INDEX($E$46:$AB$47,2,MATCH(Main!F30,$E$46:$AB$46,0))) | G30: =IF(Main!G30="","",INDEX($E$46:$AB$47,2,MATCH(Main!G30,$E$46:$AB$46,0))) | H30: =IF(Main!H30="","",INDEX($E$46:$AB$47,2,MATCH(Main!H30,$E$46:$AB$46,0))) | I30: =IF(Main!I30="","",INDEX($E$46:$AB$47,2,MATCH(Main!I30,$E$46:$AB$46,0))) | J30: =IF(Main!J30="","",INDEX($E$46:$AB$47,2,MATCH(Main!J30,$E$46:$AB$46,0))) | K30: =IF(Main!K30="","",INDEX($E$46:$AB$47,2,MATCH(Main!K30,$E$46:$AB$46,0))) | L30: =IF(Main!L30="","",INDEX($E$46:$AB$47,2,MATCH(Main!L30,$E$46:$AB$46,0))) | ... AI30: =IF(Main!AI30="","",INDEX($E$46:$AB$47,2,MATCH(Main!AI30,$E$46:$AB$46,0))) | AJ30: =COUNTIF(Main!E30:'Main'!AI30,"К") -> 0 | AK30: =COUNTIF(Main!E30:'Main'!AI30,"П") -> 0 | AL30: =COUNTIF(Main!E30:'Main'!AI30,"Б") -> 0 | AM30: =COUNTIF(Main!E30:'Main'!AI30,"О") -> 0 | AN30: =COUNTIF(Main!E30:'Main'!AI30,"АО") -> 0 | AO30: =SUMIF($E$43:$AI$43,"В",Main!E30:'Main'!AI30) -> 0 | AR30: =COUNTIF(E30:AI30,">0") -> 0 | AS30: =SUM(E30:AI30) -> 0 | AT30: 19 | AU30: 152
A31: 18 | B31: 39962 | C31: Климов Е.Н. | D31: эл/мех | E31: =IF(Main!E31="","",INDEX($E$46:$AB$47,2,MATCH(Main!E31,$E$46:$AB$46,0))) | F31: =IF(Main!F31="","",INDEX($E$46:$AB$47,2,MATCH(Main!F31,$E$46:$AB$46,0))) -> 8 | G31: =IF(Main!G31="","",INDEX($E$46:$AB$47,2,MATCH(Main!G31,$E$46:$AB$46,0))) -> 8 | H31: =IF(Main!H31="","",INDEX($E$46:$AB$47,2,MATCH(Main!H31,$E$46:$AB$46,0))) -> 4 | I31: =IF(Main!I31="","",INDEX($E$46:$AB$47,2,MATCH(Main!I31,$E$46:$AB$46,0))) -> 8 | J31: =IF(Main!J31="","",INDEX($E$46:$AB$47,2,MATCH(Main!J31,$E$46:$AB$46,0))) -> 8 | K31: =IF(Main!K31="","",INDEX($E$46:$AB$47,2,MATCH(Main!K31,$E$46:$AB$46,0))) | L31: =IF(Main!L31="","",INDEX($E$46:$AB$47,2,MATCH(Main!L31,$E$46:$AB$46,0))) | ... AI31: =IF(Main!AI31="","",INDEX($E$46:$AB$47,2,MATCH(Main!AI31,$E$46:$AB$46,0))) | AJ31: =COUNTIF(Main!E31:'Main'!AI31,"К") -> 0 | AK31: =COUNTIF(Main!E31:'Main'!AI31,"П") -> 0 | AL31: =COUNTIF(Main!E31:'Main'!AI31,"Б") -> 0 | AM31: =COUNTIF(Main!E31:'Main'!AI31,"О") -> 0 | AN31: =COUNTIF(Main!E31:'Main'!AI31,"АО") -> 0 | AO31: =SUMIF($E$43:$AI$43,"В",Main!E31:'Main'!AI31) -> 0 | AR31: =COUNTIF(E31:AI31,">0") -> 5 | AS31: =SUM(E31:AI31) -> 36 | AT31: 19 | AU31: 152
A32: 19 | B32: 85743 | C32: Рудиков Д.А. | D32: слес-рем | E32: =IF(Main!E32="","",INDEX($E$46:$AB$47,2,MATCH(Main!E32,$E$46:$AB$46,0))) | F32: =IF(Main!F32="","",INDEX($E$46:$AB$47,2,MATCH(Main!F32,$E$46:$AB$46,0))) -> 8 | G32: =IF(Main!G32="","",INDEX($E$46:$AB$47,2,MATCH(Main!G32,$E$46:$AB$46,0))) -> 8 | H32: =IF(Main!H32="","",INDEX($E$46:$AB$47,2,MATCH(Main!H32,$E$46:$AB$46,0))) -> 8 | I32: =IF(Main!I32="","",INDEX($E$46:$AB$47,2,MATCH(Main!I32,$E$46:$AB$46,0))) -> 8 | J32: =IF(Main!J32="","",INDEX($E$46:$AB$47,2,MATCH(Main!J32,$E$46:$AB$46,0))) -> 8 | K32: =IF(Main!K32="","",INDEX($E$46:$AB$47,2,MATCH(Main!K32,$E$46:$AB$46,0))) | L32: =IF(Main!L32="","",INDEX($E$46:$AB$47,2,MATCH(Main!L32,$E$46:$AB$46,0))) | ... AI32: =IF(Main!AI32="","",INDEX($E$46:$AB$47,2,MATCH(Main!AI32,$E$46:$AB$46,0))) | AJ32: =COUNTIF(Main!E32:'Main'!AI32,"К") -> 0 | AK32: =COUNTIF(Main!E32:'Main'!AI32,"П") -> 0 | AL32: =COUNTIF(Main!E32:'Main'!AI32,"Б") -> 0 | AM32: =COUNTIF(Main!E32:'Main'!AI32,"О") -> 0 | AN32: =COUNTIF(Main!E32:'Main'!AI32,"АО") -> 0 | AO32: =SUMIF($E$43:$AI$43,"В",Main!E32:'Main'!AI32) -> 0 | AR32: =COUNTIF(E32:AI32,">0") -> 5 | AS32: =SUM(E32:AI32) -> 40 | AT32: 19 | AU32: 152
AJ33: =COUNTIF(Main!E33:'Main'!AI33,"К") -> 0 | AK33: =COUNTIF(Main!E33:'Main'!AI33,"П") -> 0 | AL33: =COUNTIF(Main!E33:'Main'!AI33,"Б") -> 0 | AM33: =COUNTIF(Main!E33:'Main'!AI33,"О") -> 0 | AN33: =COUNTIF(Main!E33:'Main'!AI33,"АО") -> 0 | AO33: =SUMIF($E$43:$AI$43,"В",Main!E33:'Main'!AI33) -> 0 | AR33: =COUNTIF(E33:AI33,">0") -> 0 | AS33: =SUM(E33:AI33) -> 0 | AT33: 19 | AU33: 152
AJ34: =COUNTIF(Main!E34:'Main'!AI34,"К") -> 0 | AK34: =COUNTIF(Main!E34:'Main'!AI34,"П") -> 0 | AL34: =COUNTIF(Main!E34:'Main'!AI34,"Б") -> 0 | AM34: =COUNTIF(Main!E34:'Main'!AI34,"О") -> 0 | AN34: =COUNTIF(Main!E34:'Main'!AI34,"АО") -> 0 | AO34: =SUMIF($E$43:$AI$43,"В",Main!E34:'Main'!AI34) -> 0 | AR34: =COUNTIF(E34:AI34,">0") -> 0 | AS34: =SUM(E34:AI34) -> 0 | AT34: 19 | AU34: 152
AJ35: =COUNTIF(Main!E35:'Main'!AI35,"К") -> 0 | AK35: =COUNTIF(Main!E35:'Main'!AI35,"П") -> 0 | AL35: =COUNTIF(Main!E35:'Main'!AI35,"Б") -> 0 | AM35: =COUNTIF(Main!E35:'Main'!AI35,"О") -> 0 | AN35: =COUNTIF(Main!E35:'Main'!AI35,"АО") -> 0 | AO35: =SUMIF($E$43:$AI$43,"В",Main!E35:'Main'!AI35) -> 0 | AR35: =COUNTIF(E35:AI35,">0") -> 0 | AS35: =SUM(E35:AI35) -> 0 | AT35: 19 | AU35: 152
AJ36: =COUNTIF(Main!E36:'Main'!AI36,"К") -> 0 | AK36: =COUNTIF(Main!E36:'Main'!AI36,"П") -> 0 | AL36: =COUNTIF(Main!E36:'Main'!AI36,"Б") -> 0 | AM36: =COUNTIF(Main!E36:'Main'!AI36,"О") -> 0 | AN36: =COUNTIF(Main!E36:'Main'!AI36,"АО") -> 0 | AO36: =SUMIF($E$43:$AI$43,"В",Main!E36:'Main'!AI36) -> 0 | AR36: =COUNTIF(E36:AI36,">0") -> 0 | AS36: =SUM(E36:AI36) -> 0 | AT36: 19 | AU36: 152
AJ37: =COUNTIF(Main!E37:'Main'!AI37,"К") -> 0 | AK37: =COUNTIF(Main!E37:'Main'!AI37,"П") -> 0 | AL37: =COUNTIF(Main!E37:'Main'!AI37,"Б") -> 0 | AM37: =COUNTIF(Main!E37:'Main'!AI37,"О") -> 0 | AN37: =COUNTIF(Main!E37:'Main'!AI37,"АО") -> 0 | AO37: =SUMIF($E$43:$AI$43,"В",Main!E37:'Main'!AI37) -> 0 | AR37: =COUNTIF(E37:AI37,">0") -> 0 | AS37: =SUM(E37:AI37) -> 0 | AT37: 19 | AU37: 152
AJ38: =COUNTIF(Main!E38:'Main'!AI38,"К") -> 0 | AK38: =COUNTIF(Main!E38:'Main'!AI38,"П") -> 0 | AL38: =COUNTIF(Main!E38:'Main'!AI38,"Б") -> 0 | AM38: =COUNTIF(Main!E38:'Main'!AI38,"О") -> 0 | AN38: =COUNTIF(Main!E38:'Main'!AI38,"АО") -> 0 | AO38: =SUMIF($E$43:$AI$43,"В",Main!E38:'Main'!AI38) -> 0 | AR38: =COUNTIF(E38:AI38,">0") -> 0 | AS38: =SUM(E38:AI38) -> 0 | AT38: 19 | AU38: 152
AJ39: =COUNTIF(Main!E39:'Main'!AI39,"К") -> 0 | AK39: =COUNTIF(Main!E39:'Main'!AI39,"П") -> 0 | AL39: =COUNTIF(Main!E39:'Main'!AI39,"Б") -> 0 | AM39: =COUNTIF(Main!E39:'Main'!AI39,"О") -> 0 | AN39: =COUNTIF(Main!E39:'Main'!AI39,"АО") -> 0 | AO39: =SUMIF($E$43:$AI$43,"В",Main!E39:'Main'!AI39) -> 0 | AR39: =COUNTIF(E39:AI39,">0") -> 0 | AS39: =SUM(E39:AI39) -> 0 | AT39: 19 | AU39: 152
E40: ВС | F40: ПН | G40: ВТ | H40: СР | I40: ЧТ | J40: ПТ | K40: СБ | L40: ВС | M40: ПН | N40: ВТ | O40: СР | P40: ЧТ | Q40: ПТ | R40: СБ | S40: ВС | T40: ПН | U40: ВТ | V40: СР | W40: ЧТ | X40: ПТ | Y40: СБ | Z40: ВС | AA40: ПН | AB40: ВТ | AC40: СР | AD40: ЧТ | AE40: ПТ | AF40: СБ | AG40: ВС | AH40: ПН | AI40: ВТ | AM40: Итого дней | AR40: =SUM(AR13:AR34) -> 89 | AT40: =SUM(AT13:AT34) -> 418
A41: Ответственное лицо | AM41: Итого часов | AS41: =SUM(AS13:AS34) -> 697 | AU41: =SUM(AU13:AU34) -> 3344
D42: должность | F42: подпись | J42: расшифровка подписи
A43: Настройка месяца | E43: В | F43: =Main!F43 -> Р | G43: =Main!G43 -> Р | H43: =Main!H43 -> Р | I43: =Main!I43 -> Р | J43: =Main!J43 -> Р | K43: =Main!K43 -> В | L43: =Main!L43 -> В | M43: =Main!M43 -> Р | ... AI43: =Main!AI43 -> х
...

Sheet NOCH
C1: АО Риф, ООО Стимул | AU1: Унифицированная форма № Т-13
C2: наименование организации | AU2: Утверждена постановлением Госкомстата РФ
C3: ПК №250 | X3: Принятые | AU3: от 5 января 2004 г. N 1
C4: наименование структурного подразделения
A5: ТАБЕЛЬ | AU5: 14
A6: учета использования рабочего времени
A7: =CONCATENATE("за ",данные!A1," месяц ",данные!B1) -> за февраль месяц 2026 года.
A8: № п/п | B8: Табельный номер | C8: Фамилия, инициалы, должность (специальность, профессия) | D8: Профессия | E8: Отметки о явках и неявках на работу по числам месяца | AJ8: Отработано за
E9: 01 | F9: 02 | G9: 03 | H9: 04 | I9: 05 | J9: 06 | K9: 07 | L9: 08 | M9: 09 | N9: 10 | O9: 11 | P9: 12 | Q9: 13 | R9: 14 | S9: 15 | T9: 16 | U9: 17 | V9: 18 | W9: 19 | X9: 20 | Y9: 21 | Z9: 22 | AA9: 23 | AB9: 24 | AC9: 25 | AD9: 26 | AE9: 27 | AF9: 28 | AG9: 29 | AH9: 30 | AI9: 31 | AJ9: Месяц | AR9: Отработано | AT9: Всего
AJ10: командиров. | AK10: прогул | AL10: боль-нич- ный | AM10: отпуск | AN10: адм. отп | AO10: празд вы- ходн | AP10: ночн. | AQ10: пере-работ- ка | AR10: дней | AS10: часов | AT10: дней | AU10: часов
A11: 1 | C11: 2 | D11: 3 | E11: 4 | AJ11: 5 | AK11: 6 | AL11: 7 | AM11: 8 | AN11: 9 | AO11: 10 | AP11: 11 | AQ11: 12 | AR11: 13 | AS11: 14 | AT11: 15 | AU11: 16
B12: АО Риф
A13: 1 | B13: 83727 | C13: Горбуненко Ф.Ф. | D13: слес-рем | E13: =IF(OR(Main!E13="",Main!E13=0),"",INDEX($E$46:$AB$47,2,MATCH(Main!E13,$E$46:$AB$46,0))) | F13: =IF(OR(Main!F13="",Main!F13=0),"",INDEX($E$46:$AB$47,2,MATCH(Main!F13,$E$46:$AB$46,0))) -> 0 | G13: =IF(OR(Main!G13="",Main!G13=0),"",INDEX($E$46:$AB$47,2,MATCH(Main!G13,$E$46:$AB$46,0))) -> 0 | H13: =IF(OR(Main!H13="",Main!H13=0),"",INDEX($E$46:$AB$47,2,MATCH(Main!H13,$E$46:$AB$46,0))) -> 0 | I13: =IF(OR(Main!I13="",Main!I13=0),"",INDEX($E$46:$AB$47,2,MATCH(Main!I13,$E$46:$AB$46,0))) -> 0 | J13: =IF(OR(Main!J13="",Main!J13=0),"",INDEX($E$46:$AB$47,2,MATCH(Main!J13,$E$46:$AB$46,0))) -> 0 | K13: =IF(OR(Main!K13="",Main!K13=0),"",INDEX($E$46:$AB$47,2,MATCH(Main!K13,$E$46:$AB$46,0))) -> 0 | L13: =IF(OR(Main!L13="",Main!L13=0),"",INDEX($E$46:$AB$47,2,MATCH(Main!L13,$E$46:$AB$46,0))) -> 0 | ... AI13: =IF(OR(Main!AI13="",Main!AI13=0),"",INDEX($E$46:$AB$47,2,MATCH(Main!AI13,$E$46:$AB$46,0))) | AP13: =SUM(E13:AI13) -> 0 | AT13: =IF(Main!AS13="","",$AJ$49) -> 19 | AU13: =IF(Main!AS13="","",$AK$49) -> 152
A14: 2 | B14: 89046 | C14: Дулов С.Д. | D14: слес-рем | E14: =IF(OR(Main!E14="",Main!E14=0),"",INDEX($E$46:$AB$47,2,MATCH(Main!E14,$E$46:$AB$46,0))) | F14: =IF(OR(Main!F14="",Main!F14=0),"",INDEX($E$46:$AB$47,2,MATCH(Main!F14,$E$46:$AB$46,0))) -> 0 | G14: =IF(OR(Main!G14="",Main!G14=0),"",INDEX($E$46:$AB$47,2,MATCH(Main!G14,$E$46:$AB$46,0))) -> 0 | H14: =IF(OR(Main!H14="",Main!H14=0),"",INDEX($E$46:$AB$47,2,MATCH(Main!H14,$E$46:$AB$46,0))) -> 0 | I14: =IF(OR(Main!I14="",Main!I14=0),"",INDEX($E$46:$AB$47,2,MATCH(Main!I14,$E$46:$AB$46,0))) -> 0 | J14: =IF(OR(Main!J14="",Main!J14=0),"",INDEX($E$46:$AB$47,2,MATCH(Main!J14,$E$46:$AB$46,0))) -> 0 | K14: =IF(OR(Main!K14="",Main!K14=0),"",INDEX($E$46:$AB$47,2,MATCH(Main!K14,$E$46:$AB$46,0))) -> 0 | L14: =IF(OR(Main!L14="",Main!L14=0),"",INDEX($E$46:$AB$47,2,MATCH(Main!L14,$E$46:$AB$46,0))) | ... AI14: =IF(OR(Main!AI14="",Main!AI14=0),"",INDEX($E$46:$AB$47,2,MATCH(Main!AI14,$E$46:$AB$46,0))) | AP14: =SUM(E14:AI14) -> 0 | AT14: =IF(Main!AS14="","",$AJ$49) -> 19 | AU14: =IF(Main!AS14="","",$AK$49) -> 152
A15: 3 | B15: 31205 | C15: Карпенко А.Г. | D15: слес-рем | E15: =IF(OR(Main!E15="",Main!E15=0),"",INDEX($E$46:$AB$47,2,MATCH(Main!E15,$E$46:$AB$46,0))) -> 0 | F15: =IF(OR(Main!F15="",Main!F15=0),"",INDEX($E$46:$AB$47,2,MATCH(Main!F15,$E$46:$AB$46,0))) -> 0 | G15: =IF(OR(Main!G15="",Main!G15=0),"",INDEX($E$46:$AB$47,2,MATCH(Main!G15,$E$46:$AB$46,0))) -> 0 | H15: =IF(OR(Main!H15="",Main!H15=0),"",INDEX($E$46:$AB$47,2,MATCH(Main!H15,$E$46:$AB$46,0))) -> 0 | I15: =IF(OR(Main!I15="",Main!I15=0),"",INDEX($E$46:$AB$47,2,MATCH(Main!I15,$E$46:$AB$46,0))) -> 0 | J15: =IF(OR(Main!J15="",Main!J15=0),"",INDEX($E$46:$AB$47,2,MATCH(Main!J15,$E$46:$AB$46,0))) -> 0 | K15: =IF(OR(Main!K15="",Main!K15=0),"",INDEX($E$46:$AB$47,2,MATCH(Main!K15,$E$46:$AB$46,0))) -> 0 | L15: =IF(OR(Main!L15="",Main!L15=0),"",INDEX($E$46:$AB$47,2,MATCH(Main!L15,$E$46:$AB$46,0))) -> 0 | ... AI15: =IF(OR(Main!AI15="",Main!AI15=0),"",INDEX($E$46:$AB$47,2,MATCH(Main!AI15,$E$46:$AB$46,0))) | AP15: =SUM(E15:AI15) -> 0 | AT15: =IF(Main!AS15="","",$AJ$49) | AU15: =IF(Main!AS15="","",$AK$49)
A16: 4 | B16: 83448 | C16: Колодный С.С. | D16: эл/мех | E16: =IF(OR(Main!E16="",Main!E16=0),"",INDEX($E$46:$AB$47,2,MATCH(Main!E16,$E$46:$AB$46,0))) -> 0 | F16: =IF(OR(Main!F16="",Main!F16=0),"",INDEX($E$46:$AB$47,2,MATCH(Main!F16,$E$46:$AB$46,0))) -> 0 | G16: =IF(OR(Main!G16="",Main!G16=0),"",INDEX($E$46:$AB$47,2,MATCH(Main!G16,$E$46:$AB$46,0))) -> 0 | H16: =IF(OR(Main!H16="",Main!H16=0),"",INDEX($E$46:$AB$47,2,MATCH(Main!H16,$E$46:$AB$46,0))) -> 0 | I16: =IF(OR(Main!I16="",Main!I16=0),"",INDEX($E$46:$AB$47,2,MATCH(Main!I16,$E$46:$AB$46,0))) -> 0 | J16: =IF(OR(Main!J16="",Main!J16=0),"",INDEX($E$46:$AB$47,2,MATCH(Main!J16,$E$46:$AB$46,0))) -> 0 | K16: =IF(OR(Main!K16="",Main!K16=0),"",INDEX($E$46:$AB$47,2,MATCH(Main!K16,$E$46:$AB$46,0))) | L16: =IF(OR(Main!L16="",Main!L16=0),"",INDEX($E$46:$AB$47,2,MATCH(Main!L16,$E$46:$AB$46,0))) | ... AI16: =IF(OR(Main!AI16="",Main!AI16=0),"",INDEX($E$46:$AB$47,2,MATCH(Main!AI16,$E$46:$AB$46,0))) | AP16: =SUM(E16:AI16) -> 0 | AT16: =IF(Main!AS16="","",$AJ$49) -> 19 | AU16: =IF(Main!AS16="","",$AK$49) -> 152
A17: 5 | B17: 21782 | C17: Котов О.А. | D17: слес-рем | E17: =IF(OR(Main!E17="",Main!E17=0),"",INDEX($E$46:$AB$47,2,MATCH(Main!E17,$E$46:$AB$46,0))) -> 0 | F17: =IF(OR(Main!F17="",Main!F17=0),"",INDEX($E$46:$AB$47,2,MATCH(Main!F17,$E$46:$AB$46,0))) -> 0 | G17: =IF(OR(Main!G17="",Main!G17=0),"",INDEX($E$46:$AB$47,2,MATCH(Main!G17,$E$46:$AB$46,0))) -> 0 | H17: =IF(OR(Main!H17="",Main!H17=0),"",INDEX($E$46:$AB$47,2,MATCH(Main!H17,$E$46:$AB$46,0))) -> 0 | I17: =IF(OR(Main!I17="",Main!I17=0),"",INDEX($E$46:$AB$47,2,MATCH(Main!I17,$E$46:$AB$46,0))) -> 0 | J17: =IF(OR(Main!J17="",Main!J17=0),"",INDEX($E$46:$AB$47,2,MATCH(Main!J17,$E$46:$AB$46,0))) -> 0 | K17: =IF(OR(Main!K17="",Main!K17=0),"",INDEX($E$46:$AB$47,2,MATCH(Main!K17,$E$46:$AB$46,0))) | L17: =IF(OR(Main!L17="",Main!L17=0),"",INDEX($E$46:$AB$47,2,MATCH(Main!L17,$E$46:$AB$46,0))) | ... AI17: =IF(OR(Main!AI17="",Main!AI17=0),"",INDEX($E$46:$AB$47,2,MATCH(Main!AI17,$E$46:$AB$46,0))) | AP17: =SUM(E17:AI17) -> 0 | AT17: =IF(Main!AS17="","",$AJ$49) -> 19 | AU17: =IF(Main!AS17="","",$AK$49) -> 152
A18: 6 | B18: 90072 | C18: Кривоконев В.И. | D18: слес-рем | E18: =IF(OR(Main!E18="",Main!E18=0),"",INDEX($E$46:$AB$47,2,MATCH(Main!E18,$E$46:$AB$46,0))) | F18: =IF(OR(Main!F18="",Main!F18=0),"",INDEX($E$46:$AB$47,2,MATCH(Main!F18,$E$46:$AB$46,0))) -> 0 | G18: =IF(OR(Main!G18="",Main!G18=0),"",INDEX($E$46:$AB$47,2,MATCH(Main!G18,$E$46:$AB$46,0))) -> 0 | H18: =IF(OR(Main!H18="",Main!H18=0),"",INDEX($E$46:$AB$47,2,MATCH(Main!H18,$E$46:$AB$46,0))) -> 0 | I18: =IF(OR(Main!I18="",Main!I18=0),"",INDEX($E$46:$AB$47,2,MATCH(Main!I18,$E$46:$AB$46,0))) -> 0 | J18: =IF(OR(Main!J18="",Main!J18=0),"",INDEX($E$46:$AB$47,2,MATCH(Main!J18,$E$46:$AB$46,0))) -> 0 | K18: =IF(OR(Main!K18="",Main!K18=0),"",INDEX($E$46:$AB$47,2,MATCH(Main!K18,$E$46:$AB$46,0))) | L18: =IF(OR(Main!L18="",Main!L18=0),"",INDEX($E$46:$AB$47,2,MATCH(Main!L18,$E$46:$AB$46,0))) | ... AI18: =IF(OR(Main!AI18="",Main!AI18=0),"",INDEX($E$46:$AB$47,2,MATCH(Main!AI18,$E$46:$AB$46,0))) | AP18: =SUM(E18:AI18) -> 0 | AT18: =IF(Main!AS18="","",$AJ$49) -> 19 | AU18: =IF(Main!AS18="","",$AK$49) -> 152
A19: 7 | B19: 63549 | C19: Лахин В.В. | D19: слес-рем | E19: =IF(OR(Main!E19="",Main!E19=0),"",INDEX($E$46:$AB$47,2,MATCH(Main!E19,$E$46:$AB$46,0))) | F19: =IF(OR(Main!F19="",Main!F19=0),"",INDEX($E$46:$AB$47,2,MATCH(Main!F19,$E$46:$AB$46,0))) -> 0 | G19: =IF(OR(Main!G19="",Main!G19=0),"",INDEX($E$46:$AB$47,2,MATCH(Main!G19,$E$46:$AB$46,0))) -> 0 | H19: =IF(OR(Main!H19="",Main!H19=0),"",INDEX($E$46:$AB$47,2,MATCH(Main!H19,$E$46:$AB$46,0))) -> 0 | I19: =IF(OR(Main!I19="",Main!I19=0),"",INDEX($E$46:$AB$47,2,MATCH(Main!I19,$E$46:$AB$46,0))) -> 0 | J19: =IF(OR(Main!J19="",Main!J19=0),"",INDEX($E$46:$AB$47,2,MATCH(Main!J19,$E$46:$AB$46,0))) -> 0 | K19: =IF(OR(Main!K19="",Main!K19=0),"",INDEX($E$46:$AB$47,2,MATCH(Main!K19,$E$46:$AB$46,0))) | L19: =IF(OR(Main!L19="",Main!L19=0),"",INDEX($E$46:$AB$47,2,MATCH(Main!L19,$E$46:$AB$46,0))) | ... AI19: =IF(OR(Main!AI19="",Main!AI19=0),"",INDEX($E$46:$AB$47,2,MATCH(Main!AI19,$E$46:$AB$46,0))) | AP19: =SUM(E19:AI19) -> 0 | AT19: =IF(Main!AS19="","",$AJ$49) -> 19 | AU19: =IF(Main!AS19="","",$AK$49) -> 152
A20: 8 | B20: 12377 | C20: Лахин С.Н. | D20: слес-рем | E20: =IF(OR(Main!E20="",Main!E20=0),"",INDEX($E$46:$AB$47,2,MATCH(Main!E20,$E$46:$AB$46,0))) | F20: =IF(OR(Main!F20="",Main!F20=0),"",INDEX($E$46:$AB$47,2,MATCH(Main!F20,$E$46:$AB$46,0))) -> 0 | G20: =IF(OR(Main!G20="",Main!G20=0),"",INDEX($E$46:$AB$47,2,MATCH(Main!G20,$E$46:$AB$46,0))) -> 0 | H20: =IF(OR(Main!H20="",Main!H20=0),"",INDEX($E$46:$AB$47,2,MATCH(Main!H20,$E$46:$AB$46,0))) -> 0 | I20: =IF(OR(Main!I20="",Main!I20=0),"",INDEX($E$46:$AB$47,2,MATCH(Main!I20,$E$46:$AB$46,0))) -> 0 | J20: =IF(OR(Main!J20="",Main!J20=0),"",INDEX($E$46:$AB$47,2,MATCH(Main!J20,$E$46:$AB$46,0))) -> 0 | K20: =IF(OR(Main!K20="",Main!K20=0),"",INDEX($E$46:$AB$47,2,MATCH(Main!K20,$E$46:$AB$46,0))) | L20: =IF(OR(Main!L20="",Main!L20=0),"",INDEX($E$46:$AB$47,2,MATCH(Main!L20,$E$46:$AB$46,0))) | ... AI20: =IF(OR(Main!AI20="",Main!AI20=0),"",INDEX($E$46:$AB$47,2,MATCH(Main!AI20,$E$46:$AB$46,0))) | AP20: =SUM(E20:AI20) -> 0 | AT20: =IF(Main!AS20="","",$AJ$49) -> 19 | AU20: =IF(Main!AS20="","",$AK$49) -> 152
A21: 9 | B21: 63558 | C21: Миньков А.А. | D21: слес-рем | E21: =IF(OR(Main!E21="",Main!E21=0),"",INDEX($E$46:$AB$47,2,MATCH(Main!E21,$E$46:$AB$46,0))) -> 0 | F21: =IF(OR(Main!F21="",Main!F21=0),"",INDEX($E$46:$AB$47,2,MATCH(Main!F21,$E$46:$AB$46,0))) -> 0 | G21: =IF(OR(Main!G21="",Main!G21=0),"",INDEX($E$46:$AB$47,2,MATCH(Main!G21,$E$46:$AB$46,0))) -> 0 | H21: =IF(OR(Main!H21="",Main!H21=0),"",INDEX($E$46:$AB$47,2,MATCH(Main!H21,$E$46:$AB$46,0))) -> 0 | I21: =IF(OR(Main!I21="",Main!I21=0),"",INDEX($E$46:$AB$47,2,MATCH(Main!I21,$E$46:$AB$46,0))) -> 0 | J21: =IF(OR(Main!J21="",Main!J21=0),"",INDEX($E$46:$AB$47,2,MATCH(Main!J21,$E$46:$AB$46,0))) -> 0 | K21: =IF(OR(Main!K21="",Main!K21=0),"",INDEX($E$46:$AB$47,2,MATCH(Main!K21,$E$46:$AB$46,0))) -> 0 | L21: =IF(OR(Main!L21="",Main!L21=0),"",INDEX($E$46:$AB$47,2,MATCH(Main!L21,$E$46:$AB$46,0))) -> 0 | ... AI21: =IF(OR(Main!AI21="",Main!AI21=0),"",INDEX($E$46:$AB$47,2,MATCH(Main!AI21,$E$46:$AB$46,0))) | AP21: =SUM(E21:AI21) -> 0 | AT21: =IF(Main!AS21="","",$AJ$49) | AU21: =IF(Main!AS21="","",$AK$49)
A22: 10 | B22: 31178 | C22: Никонов Н.А. | D22: слес-рем | E22: =IF(OR(Main!E22="",Main!E22=0),"",INDEX($E$46:$AB$47,2,MATCH(Main!E22,$E$46:$AB$46,0))) | F22: =IF(OR(Main!F22="",Main!F22=0),"",INDEX($E$46:$AB$47,2,MATCH(Main!F22,$E$46:$AB$46,0))) -> 0 | G22: =IF(OR(Main!G22="",Main!G22=0),"",INDEX($E$46:$AB$47,2,MATCH(Main!G22,$E$46:$AB$46,0))) -> 0 | H22: =IF(OR(Main!H22="",Main!H22=0),"",INDEX($E$46:$AB$47,2,MATCH(Main!H22,$E$46:$AB$46,0))) -> 0 | I22: =IF(OR(Main!I22="",Main!I22=0),"",INDEX($E$46:$AB$47,2,MATCH(Main!I22,$E$46:$AB$46,0))) -> 0 | J22: =IF(OR(Main!J22="",Main!J22=0),"",INDEX($E$46:$AB$47,2,MATCH(Main!J22,$E$46:$AB$46,0))) -> 0 | K22: =IF(OR(Main!K22="",Main!K22=0),"",INDEX($E$46:$AB$47,2,MATCH(Main!K22,$E$46:$AB$46,0))) | L22: =IF(OR(Main!L22="",Main!L22=0),"",INDEX($E$46:$AB$47,2,MATCH(Main!L22,$E$46:$AB$46,0))) | ... AI22: =IF(OR(Main!AI22="",Main!AI22=0),"",INDEX($E$46:$AB$47,2,MATCH(Main!AI22,$E$46:$AB$46,0))) | AP22: =SUM(E22:AI22) -> 0 | AT22: =IF(Main!AS22="","",$AJ$49) -> 19 | AU22: =IF(Main!AS22="","",$AK$49) -> 152
A23: 11 | B23: 21116 | C23: Переверзев А.М. | D23: слес-рем | E23: =IF(OR(Main!E23="",Main!E23=0),"",INDEX($E$46:$AB$47,2,MATCH(Main!E23,$E$46:$AB$46,0))) | F23: =IF(OR(Main!F23="",Main!F23=0),"",INDEX($E$46:$AB$47,2,MATCH(Main!F23,$E$46:$AB$46,0))) -> 0 | G23: =IF(OR(Main!G23="",Main!G23=0),"",INDEX($E$46:$AB$47,2,MATCH(Main!G23,$E$46:$AB$46,0))) -> 0 | H23: =IF(OR(Main!H23="",Main!H23=0),"",INDEX($E$46:$AB$47,2,MATCH(Main!H23,$E$46:$AB$46,0))) -> 0 | I23: =IF(OR(Main!I23="",Main!I23=0),"",INDEX($E$46:$AB$47,2,MATCH(Main!I23,$E$46:$AB$46,0))) -> 0 | J23: =IF(OR(Main!J23="",Main!J23=0),"",INDEX($E$46:$AB$47,2,MATCH(Main!J23,$E$46:$AB$46,0))) -> 0 | K23: =IF(OR(Main!K23="",Main!K23=0),"",INDEX($E$46:$AB$47,2,MATCH(Main!K23,$E$46:$AB$46,0))) | L23: =IF(OR(Main!L23="",Main!L23=0),"",INDEX($E$46:$AB$47,2,MATCH(Main!L23,$E$46:$AB$46,0))) | ... AI23: =IF(OR(Main!AI23="",Main!AI23=0),"",INDEX($E$46:$AB$47,2,MATCH(Main!AI23,$E$46:$AB$46,0))) | AP23: =SUM(E23:AI23) -> 0 | AT23: =IF(Main!AS23="","",$AJ$49) -> 19 | AU23: =IF(Main!AS23="","",$AK$49) -> 152
A24: 12 | B24: 66051 | C24: Табалин П.А. | D24: эл/мех | E24: =IF(OR(Main!E24="",Main!E24=0),"",INDEX($E$46:$AB$47,2,MATCH(Main!E24,$E$46:$AB$46,0))) | F24: =IF(OR(Main!F24="",Main!F24=0),"",INDEX($E$46:$AB$47,2,MATCH(Main!F24,$E$46:$AB$46,0))) -> 0 | G24: =IF(OR(Main!G24="",Main!G24=0),"",INDEX($E$46:$AB$47,2,MATCH(Main!G24,$E$46:$AB$46,0))) -> 0 | H24: =IF(OR(Main!H24="",Main!H24=0),"",INDEX($E$46:$AB$47,2,MATCH(Main!H24,$E$46:$AB$46,0))) -> 0 | I24: =IF(OR(Main!I24="",Main!I24=0),"",INDEX($E$46:$AB$47,2,MATCH(Main!I24,$E$46:$AB$46,0))) -> 0 | J24: =IF(OR(Main!J24="",Main!J24=0),"",INDEX($E$46:$AB$47,2,MATCH(Main!J24,$E$46:$AB$46,0))) -> 0 | K24: =IF(OR(Main!K24="",Main!K24=0),"",INDEX($E$46:$AB$47,2,MATCH(Main!K24,$E$46:$AB$46,0))) | L24: =IF(OR(Main!L24="",Main!L24=0),"",INDEX($E$46:$AB$47,2,MATCH(Main!L24,$E$46:$AB$46,0))) | ... AI24: =IF(OR(Main!AI24="",Main!AI24=0),"",INDEX($E$46:$AB$47,2,MATCH(Main!AI24,$E$46:$AB$46,0))) | AP24: =SUM(E24:AI24) -> 0 | AT24: =IF(Main!AS24="","",$AJ$49) -> 19 | AU24: =IF(Main!AS24="","",$AK$49) -> 152
... A29: 17 | B29: 12512 | C29: Столповский А.В. | D29: механик | E29: =IF(OR(Main!E29="",Main!E29=0),"",INDEX($E$46:$AB$47,2,MATCH(Main!E29,$E$46:$AB$46,0))) | F29: =IF(OR(Main!F29="",Main!F29=0),"",INDEX($E$46:$AB$47,2,MATCH(Main!F29,$E$46:$AB$46,0))) -> 0 | G29: =IF(OR(Main!G29="",Main!G29=0),"",INDEX($E$46:$AB$47,2,MATCH(Main!G29,$E$46:$AB$46,0))) -> 0 | H29: =IF(OR(Main!H29="",Main!H29=0),"",INDEX($E$46:$AB$47,2,MATCH(Main!H29,$E$46:$AB$46,0))) -> 0 | I29: =IF(OR(Main!I29="",Main!I29=0),"",INDEX($E$46:$AB$47,2,MATCH(Main!I29,$E$46:$AB$46,0))) -> 0 | J29: =IF(OR(Main!J29="",Main!J29=0),"",INDEX($E$46:$AB$47,2,MATCH(Main!J29,$E$46:$AB$46,0))) -> 0 | K29: =IF(OR(Main!K29="",Main!K29=0),"",INDEX($E$46:$AB$47,2,MATCH(Main!K29,$E$46:$AB$46,0))) | L29: =IF(OR(Main!L29="",Main!L29=0),"",INDEX($E$46:$AB$47,2,MATCH(Main!L29,$E$46:$AB$46,0))) | ... AI29: =IF(OR(Main!AI29="",Main!AI29=0),"",INDEX($E$46:$AB$47,2,MATCH(Main!AI29,$E$46:$AB$46,0))) | AP29: =SUM(E29:AI29) -> 0 | AT29: =IF(Main!AS29="","",$AJ$49) -> 19 | AU29: =IF(Main!AS29="","",$AK$49) -> 152
B30: ООО Стимул | E30: =IF(OR(Main!E30="",Main!E30=0),"",INDEX($E$46:$AB$47,2,MATCH(Main!E30,$E$46:$AB$46,0))) | F30: =IF(OR(Main!F30="",Main!F30=0),"",INDEX($E$46:$AB$47,2,MATCH(Main!F30,$E$46:$AB$46,0))) | G30: =IF(OR(Main!G30="",Main!G30=0),"",INDEX($E$46:$AB$47,2,MATCH(Main!G30,$E$46:$AB$46,0))) | H30: =IF(OR(Main!H30="",Main!H30=0),"",INDEX($E$46:$AB$47,2,MATCH(Main!H30,$E$46:$AB$46,0))) | I30: =IF(OR(Main!I30="",Main!I30=0),"",INDEX($E$46:$AB$47,2,MATCH(Main!I30,$E$46:$AB$46,0))) | J30: =IF(OR(Main!J30="",Main!J30=0),"",INDEX($E$46:$AB$47,2,MATCH(Main!J30,$E$46:$AB$46,0))) | K30: =IF(OR(Main!K30="",Main!K30=0),"",INDEX($E$46:$AB$47,2,MATCH(Main!K30,$E$46:$AB$46,0))) | L30: =IF(OR(Main!L30="",Main!L30=0),"",INDEX($E$46:$AB$47,2,MATCH(Main!L30,$E$46:$AB$46,0))) | ... AI30: =IF(OR(Main!AI30="",Main!AI30=0),"",INDEX($E$46:$AB$47,2,MATCH(Main!AI30,$E$46:$AB$46,0))) | AP30: =SUM(E30:AI30) -> 0 | AT30: =IF(Main!AS30="","",$AJ$49) | AU30: =IF(Main!AS30="","",$AK$49)
A31: 18 | B31: 39962 | C31: Климов Е.Н. | D31: эл/мех | E31: =IF(OR(Main!E31="",Main!E31=0),"",INDEX($E$46:$AB$47,2,MATCH(Main!E31,$E$46:$AB$46,0))) | F31: =IF(OR(Main!F31="",Main!F31=0),"",INDEX($E$46:$AB$47,2,MATCH(Main!F31,$E$46:$AB$46,0))) -> 0 | G31: =IF(OR(Main!G31="",Main!G31=0),"",INDEX($E$46:$AB$47,2,MATCH(Main!G31,$E$46:$AB$46,0))) -> 0 | H31: =IF(OR(Main!H31="",Main!H31=0),"",INDEX($E$46:$AB$47,2,MATCH(Main!H31,$E$46:$AB$46,0))) -> 0 | I31: =IF(OR(Main!I31="",Main!I31=0),"",INDEX($E$46:$AB$47,2,MATCH(Main!I31,$E$46:$AB$46,0))) -> 0 | J31: =IF(OR(Main!J31="",Main!J31=0),"",INDEX($E$46:$AB$47,2,MATCH(Main!J31,$E$46:$AB$46,0))) -> 0 | K31: =IF(OR(Main!K31="",Main!K31=0),"",INDEX($E$46:$AB$47,2,MATCH(Main!K31,$E$46:$AB$46,0))) | L31: =IF(OR(Main!L31="",Main!L31=0),"",INDEX($E$46:$AB$47,2,MATCH(Main!L31,$E$46:$AB$46,0))) | ... AI31: =IF(OR(Main!AI31="",Main!AI31=0),"",INDEX($E$46:$AB$47,2,MATCH(Main!AI31,$E$46:$AB$46,0))) | AP31: =SUM(E31:AI31) -> 0 | AT31: =IF(Main!AS31="","",$AJ$49) -> 19 | AU31: =IF(Main!AS31="","",$AK$49) -> 152
